Workbook
Name _2010: [1]Ingresos!$A$63
Name _2011: [1]Ingresos!$A$75
Name _2012: [1]Ingresos!$A$87
Name _2013: [1]Ingresos!$A$99
Name _2014: [1]Ingresos!$A$111
Name _2015: [1]Ingresos!$A$123
Name _2016: [1]Ingresos!$A$135
Name _3.1_Total_variaciones_anuales_de_salarios_por_región: Índice!$B$15
Name _3.1_Total_variaciones_de_salarios_por_región: '3.1 V.A Salarios'!$A$10
Name _3.2_Total_variaciones_año_corrido_salarios_año_corrido: Índice!$B$16
Name _3.3_Total_variaciones_salarios_12_meses: '3.3 V.12Meses Salarios'!$A$10
Name _4.2_VAR_Trienales: Índice!#REF!
Name _fechaActualiza: #REF!
Name _fechaActualiza: #REF!
Name _fechaActualiza: #REF!
Name _fechaActualiza: #REF!
Name _fechaActualiza: #REF!
Name _fechaActualiza: #REF!
Name _fechaActualiza: #REF!
Name _fechaActualiza: #REF!
Name _fechaActualiza: #REF!
Name _fechaActualiza: #REF!
Name _fechaActualiza: #REF!
Name _fechaActualiza: #REF!
Name _fechaActualiza: #REF!
Name _fechaActualiza: #REF!
Name _fechaActualiza: #REF!
Name _fechaActualiza: #REF!
Name _fechaActualiza: #REF!
Name _fechaActualiza: #REF!
Name _FileSalida: #REF!
Name _FileSalida: #REF!
Name _FileSalida: #REF!
Name _FileSalida: #REF!
Name _FileSalida: #REF!
Name _FileSalida: #REF!
Name _FileSalida: #REF!
Name _FileSalida: #REF!
Name _FileSalida: #REF!
Name _FileSalida: #REF!
Name _FileSalida: #REF!
Name _FileSalida: #REF!
Name _FileSalida: #REF!
Name _FileSalida: #REF!
Name _FileSalida: #REF!
Name _FileSalida: #REF!
Name _FileSalida: #REF!
Name _FileSalida: #REF!
Name _um: #REF!
Name _um: #REF!
Name _um: #REF!
Name _um: #REF!
Name _um: #REF!
Name _um: #REF!
Name _um: #REF!
Name _um: #REF!
Name _um: #REF!
Name _um: #REF!
Name _um: #REF!
Name _um: #REF!

Sheet Índice
A4: ENCUESTA MENSUAL DE ALOJAMIENTO - EMA
A6: Temática de Servicios
A9: 1.1 | B9: Variaciones anuales de los ingresos reales
A10: 1.2 | B10: Variaciones año corrido de los ingresos reales
A11: 1.3 | B11: Variaciones 12 meses de los ingresos reales
A12: 2.1 | B12: Variaciones anuales del personal total y por categoría
A13: 2.2 | B13: Variaciones año corrido del personal total y por categoría
A14: 2.3 | B14: Variaciones 12 meses del personal total y por categoría
A15: 3.1 | B15: Total variaciones anuales de los salarios reales
A16: 3.2 | B16: Variaciones año corrido de los salarios reales
A17: 3.3 | B17: Variaciones 12 meses de los salarios reales
A18: 4.1 | B18: Variaciones cuatrienales de ingresos reales, personal ocupado y salarios
A19: 5.1 | B19: Porcentaje de ocupación por escala de habitación
A20: 5.2 | B20: Porcentaje de ocupación mensual
... A33: 10.2 | B33: Coeficientes de variación estimado porcentual Total regional

Sheet 1.1 V.A Ing.real
L4: Inicio
A7: ENCUESTA MENSUAL DE ALOJAMIENTO - EMA
A10: 1.1 Variaciones anuales de los ingresos reales
A11: Total nacional y 12 regiones
A12: Enero 2020 - junio 2023
A14: Año | B14: Meses | C14: Total nacional | D14: Bogotá D.C. | E14: Cartagena | F14: Central | G14: Caribe | H14: Eje Cafetero | I14: Antioquia | J14: San Andrés y Providencia | K14: Pacífico | L14: Santanderes | M14: Llanos Orinoquía | N14: Golfo de Morrosquillo y Sabana | O14: Amazonía
A15: 2020(p) | B15: Enero | C15: 8.1967281 | D15: 4.1467414 | E15: 10.435994 | F15: 3.8406836 | G15: 11.93649 | H15: 17.27755 | I15: 10.44138 | J15: 1.9028388 | K15: 8.3234261 | L15: 12.26889 | M15: -0.3067347 | N15: 11.291285 | O15: 13.939763
B16: Febrero | C16: 10.428449 | D16: 6.9182123 | E16: 9.6226209 | F16: 6.242826 | G16: 29.292856 | H16: 6.4132263 | I16: 14.181483 | J16: 10.424263 | K16: 6.8799719 | L16: 4.7508299 | M16: -3.969739 | N16: 5.3559698 | O16: 5.5832821
B17: Marzo | C17: -45.140552 | D17: -42.855218 | E17: -49.800372 | F17: -52.639079 | G17: -51.355605 | H17: -51.794764 | I17: -42.789891 | J17: -32.146477 | K17: -42.32482 | L17: -39.8188 | M17: -42.092035 | N17: -46.712462 | O17: -50.177607
B18: Abril | C18: -94.939363 | D18: -88.300777 | E18: -98.939745 | F18: -97.342983 | G18: -96.449881 | H18: -97.656197 | I18: -94.58228 | J18: -100 | K18: -95.281421 | L18: -92.163663 | M18: -94.868589 | N18: -98.51029 | O18: -95.548391
B19: Mayo | C19: -94.637033 | D19: -91.060351 | E19: -98.544875 | F19: -93.063484 | G19: -95.615601 | H19: -96.062376 | I19: -93.910449 | J19: -100 | K19: -93.616459 | L19: -91.703707 | M19: -92.198219 | N19: -98.099171 | O19: -95.162313
B20: Junio | C20: -92.892186 | D20: -86.687489 | E20: -98.219717 | F20: -96.310758 | G20: -94.029161 | H20: -97.040292 | I20: -90.953062 | J20: -100 | K20: -91.489448 | L20: -87.703051 | M20: -81.408533 | N20: -93.591938 | O20: -92.523643
B21: Julio | C21: -91.830439 | D21: -88.641558 | E21: -98.408892 | F21: -93.584297 | G21: -92.241414 | H21: -92.460284 | I21: -86.547205 | J21: -100 | K21: -87.689559 | L21: -82.81047 | M21: -72.821643 | N21: -88.474503 | O21: -90.87433
B22: Agosto | C22: -91.456809 | D22: -88.178083 | E22: -98.648906 | F22: -90.494722 | G22: -92.752885 | H22: -86.079945 | I22: -88.523784 | J22: -99.992703 | K22: -86.52842 | L22: -81.322453 | M22: -71.799247 | N22: -87.071053 | O22: -89.128444
B23: Septiembre | C23: -83.139775 | D23: -85.282075 | E23: -93.014037 | F23: -74.829423 | G23: -80.456933 | H23: -60.724504 | I23: -76.296098 | J23: -99.997765 | K23: -73.298505 | L23: -65.541355 | M23: -49.37887 | N23: -70.463779 | O23: -86.350197
B24: Octubre | C24: -64.552273 | D24: -78.027833 | E24: -66.696476 | F24: -43.845798 | G24: -47.134245 | H24: -31.532461 | I24: -59.322915 | J24: -87.167353 | K24: -59.251428 | L24: -48.427059 | M24: -13.732378 | N24: -51.905076 | O24: -85.226288
B25: Noviembre | C25: -58.453198 | D25: -69.240934 | E25: -65.467793 | F25: -41.420224 | G25: -44.096798 | H25: -30.674106 | I25: -54.081162 | J25: -76.086326 | K25: -47.487897 | L25: -38.571621 | M25: -17.70592 | N25: -33.314342 | O25: -81.633676
B26: Diciembre | C26: -49.127685 | D26: -61.322012 | E26: -57.681545 | F26: -32.291266 | G26: -33.562348 | H26: -23.823126 | I26: -43.974507 | J26: -59.813017 | K26: -44.692207 | L26: -35.637555 | M26: -20.17707 | N26: -23.168521 | O26: -78.97504
A27: 2021(p) | B27: Enero | C27: -45.582952 | D27: -67.218558 | E27: -50.636988 | F27: -33.560881 | G27: -20.055619 | H27: -31.47137 | I27: -46.669525 | J27: -49.356753 | K27: -49.089427 | L27: -26.353904 | M27: -18.376102 | N27: -19.714587 | O27: -70.822272
B28: Febrero | C28: -52.149651 | D28: -70.585246 | E28: -60.934753 | F28: -26.319473 | G28: -35.656609 | H28: -27.982265 | I28: -46.792713 | J28: -44.469016 | K28: -48.15367 | L28: -28.55244 | M28: -18.971101 | N28: -10.498681 | O28: -77.819966
B29: Marzo | C29: 14.872578 | D29: -35.041239 | E29: 18.17462 | F29: 114.5106 | G29: 58.70925 | H29: 84.601143 | I29: 20.406651 | J29: 4.6172003 | K29: 24.613944 | L29: 45.825006 | M29: 64.543621 | N29: 72.418151 | O29: -49.773298
B30: Abril | C30: 990.54654 | D30: 184.60632 | E30: 5543.4374 | F30: 2522.8841 | G30: 1437.3168 | H30: 3109.9877 | I30: 864.74315 | J30: - | K30: 1308.8679 | L30: 900.57506 | M30: 1351.3464 | N30: 4701.6777 | O30: 429.48575
B31: Mayo | C31: 809.78247 | D31: 227.92822 | E31: 3451.1201 | F31: 839.11498 | G31: 1488.3289 | H31: 1024.8611 | I31: 744.81774 | J31: - | K31: 501.82585 | L31: 728.78536 | M31: 789.25025 | N31: 3593.0647 | O31: 314.51001
B32: Junio | C32: 868.56572 | D32: 206.01719 | E32: 4451.7254 | F32: 2028.7108 | G32: 1519.878 | H32: 2375.299 | I32: 619.27595 | J32: - | K32: 538.84632 | L32: 507.2108 | M32: 536.6438 | N32: 1275.9844 | O32: 252.0486
B33: Julio | C33: 883.07794 | D33: 288.70776 | E33: 5653.9293 | F33: 1469.5041 | G33: 1321.402 | H33: 1222.1014 | I33: 502.81597 | J33: - | K33: 481.22767 | L33: 429.86195 | M33: 380.80453 | N33: 880.72621 | O33: 318.75249
B34: Agosto | C34: 821.49491 | D34: 315.08055 | E34: 6244.3616 | F34: 907.00211 | G34: 1274.7956 | H34: 536.15505 | I34: 584.1992 | J34: * | K34: 479.66067 | L34: 398.15826 | M34: 367.35013 | N34: 735.62637 | O34: 432.59979
B35: Septiembre | C35: 391.66597 | D35: 257.24632 | E35: 1248.9913 | F35: 313.01927 | G35: 443.4124 | H35: 166.08364 | I35: 263.82718 | J35: * | K35: 218.6663 | L35: 180.18945 | M35: 145.24363 | N35: 264.75208 | O35: 314.89337
B36: Octubre | C36: 173.44285 | D36: 177.82043 | E36: 235.05333 | F36: 117.18083 | G36: 170.33792 | H36: 68.715645 | I36: 145.89339 | J36: 663.03274 | K36: 115.76168 | L36: 115.04546 | M36: 54.854992 | N36: 139.6269 | O36: 354.68799
B37: Noviembre | C37: 131.86844 | D37: 127.33921 | E37: 202.89389 | F37: 72.117379 | G37: 112.6664 | H37: 55.456656 | I37: 120.43713 | J37: 323.49544 | K37: 108.77033 | L37: 72.854724 | M37: 52.176907 | N37: 95.903 | O37: 301.3334
B38: Diciembre | C38: 102.23313 | D38: 94.907325 | E38: 163.64361 | F38: 62.010846 | G38: 80.095196 | H38: 55.130596 | I38: 91.240445 | J38: 148.44625 | K38: 93.157088 | L38: 76.101571 | M38: 43.212633 | N38: 77.970756 | O38: 284.55256
A39: 2022(p) | B39: Enero | C39: 79.298886 | D39: 98.011705 | E39: 109.95449 | F39: 62.142505 | G39: 47.236301 | H39: 45.15592 | I39: 87.535721 | J39: 101.83948 | K39: 67.497578 | L39: 50.229834 | M39: 39.784176 | N39: 51.0056 | O39: 149.88497
B40: Febrero | C40: 84.890988 | D40: 121.32241 | E40: 147.25259 | F40: 38.911692 | G40: 51.631157 | H40: 41.463746 | I40: 77.925631 | J40: 75.07962 | K40: 60.683362 | L40: 41.886047 | M40: 24.492859 | N40: 28.2593 | O40: 284.58735
B41: Marzo | C41: 68.755549 | D41: 140.44915 | E41: 93.237628 | F41: 6.9803765 | G41: 56.736938 | H41: 23.854488 | I41: 67.55545 | J41: 45.512348 | K41: 39.204717 | L41: 33.155992 | M41: 8.8624599 | N41: 23.124363 | O41: 329.53363
B42: Abril | C42: 109.23225 | D42: 152.99557 | E42: 125.82107 | F42: 75.633429 | G42: 161.08926 | H42: 75.795252 | I42: 149.5382 | J42: 42.864647 | K42: 55.777782 | L42: 50.941206 | M42: 52.08901 | N42: 91.984988 | O42: 360.91977
B43: Mayo | C43: 112.9045 | D43: 172.51442 | E43: 143.83941 | F43: 71.622935 | G43: 88.66456 | H43: 160.02987 | I43: 120.21668 | J43: 29.064093 | K43: 138.78527 | L43: 69.293298 | M43: 50.677351 | N43: 47.779394 | O43: 416.53424
B44: Junio | C44: 57.294006 | D44: 115.71515 | E44: 73.698122 | F44: 26.120936 | G44: 29.999695 | H44: 47.205097 | I44: 74.384564 | J44: 6.544122 | K44: 60.562927 | L44: 44.812889 | M44: 22.21404 | N44: 34.361996 | O44: 286.02218
B45: Julio | C45: 46.039571 | D45: 94.968159 | E45: 58.075341 | F45: 24.385293 | G45: 27.516278 | H45: 39.719083 | I45: 48.88472 | J45: 1.8888607 | K45: 58.441134 | L45: 33.983623 | M45: 20.954013 | N45: 27.239464 | O45: 120.10133
B46: Agosto | C46: 36.236215 | D46: 72.10284 | E46: 52.188319 | F46: 8.4542738 | G46: 17.190714 | H46: 32.146544 | I46: 46.208249 | J46: -3.3278011 | K46: 34.31596 | L46: 14.776263 | M46: 14.343184 | N46: 24.92593 | O46: 52.141243
B47: Septiembre | C47: 31.055838 | D47: 70.664333 | E47: 48.396262 | F47: 4.3339381 | G47: 10.433064 | H47: 19.864555 | I47: 31.875386 | J47: -1.9734745 | K47: 14.414356 | L47: 7.3577425 | M47: 5.4707696 | N47: 17.053226 | O47: 45.282006
B48: Octubre | C48: 15.432735 | D48: 59.754011 | E48: 15.6438 | F48: -6.7186816 | G48: -8.5280088 | H48: 5.3076362 | I48: 26.890761 | J48: -12.701241 | K48: 15.237225 | L48: -1.3933859 | M48: 1.3526237 | N48: 4.7009062 | O48: 34.494415
...

Sheet 1.2 V.A.C Ing.real
L4: Inicio
A7: ENCUESTA MENSUAL DE ALOJAMIENTO - EMA
A10: 1.2 Variaciones año corrido de los ingresos reales
A11: Total nacional y 12 regiones
A12: ='1.1 V.A Ing.real'!A12 -> Enero 2020 - junio 2023
A14: Año | B14: Meses | C14: Total nacional | D14: Bogotá D.C. | E14: Cartagena | F14: Central | G14: Caribe | H14: Eje Cafetero | I14: Antioquia | J14: San Andrés y Providencia | K14: Pacífico | L14: Santanderes | M14: Llanos Orinoquía | N14: Golfo de Morrosquillo y Sabana | O14: Amazonía
A15: 2020(p) | B15: Enero | C15: 8.1967281 | D15: 4.1467414 | E15: 10.435994 | F15: 3.8406836 | G15: 11.93649 | H15: 17.27755 | I15: 10.44138 | J15: 1.9028388 | K15: 8.3234261 | L15: 12.26889 | M15: -0.3067347 | N15: 11.291285 | O15: 13.939763
B16: Febrero | C16: 9.2605822 | D16: 5.7300651 | E16: 10.066308 | F16: 4.7756755 | G16: 19.245235 | H16: 12.989525 | I16: 12.259593 | J16: 5.6606593 | K16: 7.5735079 | L16: 8.4743823 | M16: -1.9526487 | N16: 8.690317 | O16: 10.362136
B17: Marzo | C17: -9.4446107 | D17: -12.74966 | E17: -9.5754974 | F17: -12.424643 | G17: -5.6663488 | H17: -7.088111 | I17: -6.7175831 | J17: -6.481617 | K17: -10.139092 | L17: -8.4768696 | M17: -15.377398 | N17: -10.006618 | O17: -7.5140031
B18: Abril | C18: -30.041091 | D18: -32.009127 | E18: -29.289866 | F18: -33.565704 | G18: -27.316829 | H18: -29.07164 | I18: -27.686503 | J18: -28.489853 | K18: -31.751214 | L18: -30.705728 | M18: -36.350361 | N18: -31.833117 | O18: -28.50381
B19: Mayo | C19: -42.925688 | D19: -46.130599 | E19: -41.134554 | F19: -43.949025 | G19: -39.211435 | H19: -41.273516 | I19: -41.466179 | J19: -41.999533 | K19: -45.688422 | L19: -43.295989 | M19: -46.405368 | N19: -44.577626 | O19: -41.861682
B20: Junio | C20: -51.296517 | D20: -53.03612 | E20: -49.096472 | F20: -54.570061 | G20: -48.578168 | H20: -51.393791 | I20: -50.181428 | J20: -52.004643 | K20: -53.977327 | L20: -51.64811 | M20: -51.03736 | N20: -53.305818 | O20: -51.259263
B21: Julio | C21: -57.450862 | D21: -58.541533 | E21: -55.949296 | F21: -60.79207 | G21: -55.243764 | H21: -57.636265 | I21: -56.177634 | J21: -59.202911 | K21: -59.336426 | L21: -56.4397 | M21: -53.691377 | N21: -58.563148 | O21: -59.043413
B22: Agosto | C22: -62.16799 | D22: -62.682691 | E22: -61.622599 | F22: -64.767303 | G22: -60.597208 | H22: -61.60218 | I22: -61.052643 | J22: -64.537535 | K22: -63.38581 | L22: -60.020224 | M22: -55.641004 | N22: -62.341241 | O22: -63.586467
B23: Septiembre | C23: -64.603368 | D23: -65.614411 | E23: -64.845807 | F23: -65.833438 | G23: -62.82528 | H23: -61.513338 | I23: -62.878897 | J23: -68.558498 | K23: -64.632275 | L23: -60.714688 | M23: -54.968191 | N23: -63.244031 | O23: -66.466745
B24: Octubre | C24: -64.597999 | D24: -67.03903 | E24: -65.019474 | F24: -63.40135 | G24: -61.297305 | H24: -58.379154 | I24: -62.516591 | J24: -70.475225 | K24: -64.030672 | L24: -59.320083 | M24: -50.672499 | N24: -61.9803 | O24: -68.701688
B25: Noviembre | C25: -63.979885 | D25: -67.27286 | E25: -65.063551 | F25: -61.088045 | G25: -59.583807 | H25: -55.754107 | I25: -61.691002 | J25: -70.997136 | K25: -62.353457 | L25: -57.173403 | M25: -47.398117 | N25: -59.264318 | O25: -70.0371
B26: Diciembre | C26: -62.570144 | D26: -66.787626 | E26: -64.290387 | F26: -58.047372 | G26: -56.88446 | H26: -52.591416 | I26: -60.079621 | J26: -69.948535 | K26: -60.698795 | L26: -55.058852 | M26: -44.460748 | N26: -55.914316 | O26: -70.926643
A27: 2021(p) | B27: Enero | C27: -45.582952 | D27: -67.218558 | E27: -50.636988 | F27: -33.560881 | G27: -20.055619 | H27: -31.47137 | I27: -46.669525 | J27: -49.356753 | K27: -49.089427 | L27: -26.353904 | M27: -18.376102 | N27: -19.714587 | O27: -70.822272
B28: Febrero | C28: -48.746735 | D28: -69.163539 | E28: -55.298557 | F28: -30.702822 | G28: -27.17873 | H28: -30.174411 | I28: -46.730436 | J28: -47.104159 | K28: -48.606407 | L28: -27.425456 | M28: -18.637955 | N28: -15.799895 | O28: -73.68844
B29: Marzo | C29: -35.494768 | D29: -60.663156 | E29: -41.915991 | F29: -7.176287 | G29: -11.551211 | H29: -11.719362 | I29: -32.536142 | J29: -35.051811 | K29: -31.924477 | L29: -10.518855 | M29: 0.39974627 | N29: 1.8284433 | O29: -69.884316
B30: Abril | C30: -17.614229 | D30: -49.904617 | E30: -23.440393 | F30: 18.015449 | G30: 5.3259088 | H30: 13.319552 | I30: -16.493108 | J30: -11.714152 | K30: -8.3940533 | L30: 16.848898 | M30: 29.135319 | N30: 27.158442 | O30: -62.470996
B31: Mayo | C31: -2.1066584 | D31: -38.878745 | E31: -8.7507158 | F31: 35.748745 | G31: 23.953957 | H31: 25.673218 | I31: -0.0128374 | J31: 11.799798 | K31: 5.1159575 | L31: 38.348521 | M31: 49.057073 | N31: 50.679663 | O31: -56.184966
B32: Junio | C32: 19.180631 | D32: -27.058964 | E32: 13.007179 | F32: 68.576937 | G32: 53.634001 | H32: 51.637277 | I32: 19.793002 | J32: 42.660245 | K32: 22.977944 | L32: 60.775664 | M32: 73.556797 | N32: 80.623636 | O32: -47.414717
B33: Julio | C33: 44.365131 | D33: -13.682374 | E33: 41.321772 | F33: 105.13586 | G33: 87.183942 | H33: 83.302893 | I33: 44.2424 | J33: 77.717812 | K33: 45.03129 | L33: 83.170627 | M33: 95.525804 | N33: 113.89172 | O33: -31.383323
B34: Agosto | C34: 68.708299 | D34: 0.87069515 | E34: 70.337051 | F34: 134.0885 | G34: 118.35913 | H34: 106.19303 | I34: 68.221482 | J34: 112.33764 | K34: 68.845497 | L34: 104.34552 | M34: 114.13174 | N34: 142.18019 | O34: -10.464923
B35: Septiembre | C35: 86.572265 | D35: 15.106197 | E35: 94.386916 | F35: 148.05539 | G35: 137.53061 | H35: 112.37963 | I35: 83.185851 | J35: 145.46451 | K35: 83.068418 | L35: 112.7133 | M35: 117.88935 | N35: 153.12764 | O35: 6.2923595
B36: Octubre | C36: 95.711282 | D36: 27.554371 | E36: 106.95423 | F36: 142.81554 | G36: 141.89444 | H36: 104.87072 | I36: 90.119268 | J36: 168.63513 | K36: 87.209343 | L36: 113.04887 | M36: 106.40531 | N36: 151.22424 | O36: 25.884665
B37: Noviembre | C37: 99.906439 | D37: 37.513727 | E37: 116.2776 | F37: 131.61457 | G37: 137.86706 | H37: 97.534852 | I37: 93.675953 | J37: 180.51178 | K37: 90.258526 | L37: 107.08402 | M37: 97.978762 | N37: 142.6438 | O37: 43.319963
B38: Diciembre | C38: 100.2066 | D38: 42.96377 | E38: 122.15668 | F38: 119.75296 | G38: 128.63233 | H38: 90.786152 | I38: 93.365067 | J38: 176.49141 | K38: 90.640691 | L38: 102.72729 | M38: 89.485132 | N38: 132.18328 | O38: 60.682179
A39: 2022(p) | B39: Enero | C39: 79.298886 | D39: 98.011705 | E39: 109.95449 | F39: 62.142505 | G39: 47.236301 | H39: 45.15592 | I39: 87.535721 | J39: 101.83948 | K39: 67.497578 | L39: 50.229834 | M39: 39.784176 | N39: 51.0056 | O39: 149.88497
B40: Febrero | C40: 81.814235 | D40: 110.85773 | E40: 124.70968 | F40: 52.393735 | G40: 49.009297 | H40: 43.74039 | I40: 82.789448 | J40: 88.892375 | K40: 63.949225 | L40: 46.226275 | M40: 33.082168 | N40: 40.735206 | O40: 196.39403
B41: Marzo | C41: 76.970144 | D41: 123.03091 | E41: 113.04687 | F41: 35.39077 | G41: 51.532284 | H41: 37.05418 | I41: 77.04108 | J41: 72.609631 | K41: 53.62948 | L41: 41.310054 | M41: 23.997591 | N41: 34.776555 | O41: 231.71486
B42: Abril | C42: 84.41233 | D42: 130.49825 | E42: 116.16164 | F42: 44.296184 | G42: 70.159061 | H42: 45.856426 | I42: 92.016154 | J42: 64.746782 | K42: 54.209323 | L42: 43.787358 | M42: 30.713138 | N42: 46.419399 | O42: 258.77665
B43: Mayo | C43: 89.375281 | D43: 139.44432 | E43: 120.71549 | F43: 48.379045 | G43: 73.13762 | H43: 58.336967 | I43: 97.174118 | J43: 57.241929 | K43: 67.031074 | L43: 48.40158 | M43: 33.834699 | N43: 46.639266 | O43: 283.66288
B44: Junio | C44: 83.000862 | D44: 134.63942 | E44: 111.47779 | F44: 43.749326 | G44: 64.113409 | H44: 56.328967 | I44: 92.79789 | J44: 46.274915 | K44: 65.906581 | L44: 47.753268 | M44: 31.69282 | N44: 44.353635 | O44: 284.1123
B45: Julio | C45: 75.663431 | D45: 127.07146 | E45: 100.56397 | F45: 39.883035 | G45: 56.759007 | H45: 53.087871 | I45: 83.508504 | J45: 37.519084 | K45: 64.466746 | L45: 45.336405 | M45: 29.804645 | N45: 41.090825 | O45: 240.29028
B46: Agosto | C46: 68.917589 | D46: 117.0587 | E46: 92.135905 | F46: 35.001416 | G46: 50.219445 | H46: 49.822105 | I46: 76.771195 | J46: 30.85843 | K46: 58.795219 | L46: 40.328163 | M46: 27.494841 | N46: 38.553063 | O46: 189.83157
B47: Septiembre | C47: 63.398645 | D47: 109.06348 | E47: 85.942299 | F47: 31.015627 | G47: 44.851037 | H47: 45.945021 | I47: 69.949601 | J47: 26.427345 | K47: 51.461316 | L47: 35.536668 | M47: 24.500896 | N47: 35.786024 | O47: 160.77175
B48: Octubre | C48: 56.348304 | D48: 100.84712 | E48: 75.774246 | F48: 25.287676 | G48: 36.915986 | H48: 40.189891 | I48: 63.792014 | J48: 21.451753 | K48: 46.173414 | L48: 30.173076 | M48: 21.336868 | N48: 31.605809 | O48: 135.12225
...

Sheet 1.3 V.12Meses Ing.real
L4: Inicio
A7: ENCUESTA MENSUAL DE ALOJAMIENTO - EMA
A10: 1.3 Variaciones 12 meses de los ingresos reales
A11: Total nacional y 12 regiones
A12: Diciembre 2020 - junio 2023
A14: Año | B14: Meses | C14: Total nacional | D14: Bogotá D.C. | E14: Cartagena | F14: Central | G14: Caribe | H14: Eje Cafetero | I14: Antioquia | J14: San Andrés y Providencia | K14: Pacífico | L14: Santanderes | M14: Llanos Orinoquía | N14: Golfo de Morrosquillo y Sabana | O14: Amazonía
A15: 2020(p) | B15: Diciembre | C15: -62.570144 | D15: -66.787626 | E15: -64.290387 | F15: -58.047372 | G15: -56.88446 | H15: -52.591416 | I15: -60.079621 | J15: -69.948535 | K15: -60.698795 | L15: -55.058852 | M15: -44.460748 | N15: -55.914316 | O15: -70.926643
A16: 2021(p) | B16: Enero | C16: -66.822105 | D16: -70.880355 | E16: -70.185789 | F16: -61.605278 | G16: -59.389359 | H16: -57.087329 | I16: -64.330024 | J16: -74.724735 | K16: -64.427368 | L16: -57.462022 | M16: -46.215104 | N16: -58.288298 | O16: -78.022633
B17: Febrero | C17: -71.301175 | D17: -76.769249 | E17: -75.877902 | F17: -63.485933 | G17: -63.14611 | H17: -59.192954 | I17: -68.508762 | J17: -78.527687 | K17: -68.259345 | L17: -59.682375 | M17: -47.48762 | N17: -59.199561 | O17: -83.231752
B18: Marzo | C18: -69.533954 | D18: -77.621287 | E18: -73.93776 | F18: -58.30005 | G18: -58.984259 | H18: -54.451549 | I18: -66.497697 | J18: -77.715739 | K18: -66.110627 | L18: -56.331651 | M18: -42.020753 | N18: -54.429115 | O18: -84.265096
B19: Abril | C19: -62.943336 | D19: -74.246273 | E19: -66.672209 | F19: -49.200528 | G19: -51.366094 | H19: -44.376554 | I19: -60.365628 | J19: -69.882532 | K19: -58.56555 | L19: -46.872398 | M19: -28.51111 | N19: -44.411658 | O19: -81.825395
B20: Mayo | C20: -55.573299 | D20: -69.391872 | E20: -59.423834 | F20: -41.085071 | G20: -42.419233 | H20: -36.38549 | I20: -52.643644 | J20: -60.599672 | K20: -51.443769 | L20: -36.98941 | M20: -15.935748 | N20: -33.144696 | O20: -79.19653
B21: Junio | C21: -44.874688 | D21: -63.802754 | E21: -48.702929 | F21: -24.536036 | G21: -27.350673 | H21: -21.159673 | I21: -42.212338 | J21: -46.662963 | K21: -41.656049 | L21: -23.870164 | M21: -0.8551185 | N21: -16.633005 | O21: -75.370637
B22: Julio | C22: -29.703461 | D22: -55.794018 | E22: -32.404227 | F22: -2.7362036 | G22: -6.6685777 | H22: -0.14725314 | I22: -26.748093 | J22: -27.567861 | K22: -27.777633 | L22: -7.6710718 | M22: 16.872684 | N22: 5.3531534 | O22: -67.623185
B23: Agosto | C23: -9.6747215 | D23: -44.633048 | E23: -10.283764 | F23: 22.505396 | G23: 20.491247 | H23: 24.527236 | I23: -5.42054 | J23: -2.9753611 | K23: -7.7975653 | L23: 13.926356 | M23: 37.058608 | N23: 32.3162 | O23: -55.854052
B24: Septiembre | C24: 12.88025 | D24: -29.302154 | E24: 14.106917 | F24: 46.695384 | G24: 48.153708 | H24: 43.433073 | I24: 16.717748 | J24: 28.956024 | K24: 13.721263 | L24: 35.755023 | M24: 55.127329 | N24: 58.136017 | O24: -42.009794
B25: Octubre | C25: 37.114517 | D25: -9.5580196 | E25: 38.721106 | F25: 70.077782 | G25: 73.015876 | H25: 58.451265 | I25: 38.7649 | J25: 68.696411 | K25: 35.519193 | L25: 57.809974 | M25: 64.81613 | N25: 85.95511 | O25: -20.009283
B26: Noviembre | C26: 66.299824 | D26: 16.423558 | E26: 72.638262 | F26: 93.461864 | G26: 99.703122 | H26: 73.382422 | I26: 65.170009 | J26: 117.32406 | K26: 61.18552 | L26: 78.154651 | M26: 75.888102 | N26: 109.36055 | O26: 10.365076
B27: Diciembre | C27: 100.2066 | D27: 42.96377 | E27: 122.15668 | F27: 119.75296 | G27: 128.63233 | H27: 90.786152 | I27: 93.365067 | J27: 176.49141 | K27: 90.640691 | L27: 102.72729 | M27: 89.485132 | N27: 132.18328 | O27: 60.682179
A28: 2022(p) | B28: Enero | C28: 135.78344 | D28: 69.257917 | E28: 183.21189 | F28: 150.11296 | G28: 149.55258 | H28: 115.5749 | I28: 125.70995 | J28: 247.67588 | K28: 116.37689 | L28: 119.06557 | M28: 101.54198 | N28: 152.58984 | O28: 129.06611
B29: Febrero | C29: 181.9647 | D29: 123.53158 | E29: 268.64873 | F29: 167.14554 | G29: 177.32267 | H29: 130.79794 | I29: 163.81111 | J29: 321.87641 | K29: 148.84367 | L29: 135.77314 | M29: 109.94586 | N29: 161.75987 | O29: 224.00636
B30: Marzo | C30: 187.5481 | D30: 160.17181 | E30: 276.28356 | F30: 143.81686 | G30: 169.75877 | H30: 118.54261 | I30: 167.56708 | J30: 328.80759 | K30: 147.20311 | L30: 129.45552 | M30: 98.84517 | N30: 147.27537 | O30: 289.26454
B31: Abril | C31: 168.68159 | D31: 158.50886 | E31: 238.67618 | F31: 125.38759 | G31: 161.15914 | H31: 102.75966 | I31: 158.26989 | J31: 252.42937 | K31: 124.82255 | L31: 109.85595 | M31: 83.7857 | N31: 130.43621 | O31: 293.44943
B32: Mayo | C32: 155.6642 | D32: 157.74893 | E32: 218.08349 | F32: 114.3486 | G32: 146.04988 | H32: 101.29408 | I32: 147.35104 | J32: 198.67103 | K32: 120.9495 | L32: 98.472891 | M32: 74.632248 | N32: 113.44446 | O32: 302.64714
B33: Junio | C33: 133.35694 | D33: 151.01009 | E33: 184.3282 | F33: 91.030939 | G33: 118.23943 | H33: 85.653649 | I33: 130.92508 | J33: 146.34876 | K33: 108.24027 | L33: 85.240104 | M33: 61.254349 | N33: 93.65361 | O33: 302.40538
B34: Julio | C34: 110.26143 | D34: 139.73329 | E34: 149.54195 | F34: 69.889223 | G34: 92.960376 | H34: 68.89 | I34: 110.01061 | J34: 105.01852 | K34: 94.04629 | L34: 71.668463 | M34: 49.209825 | N34: 73.913659 | O34: 269.32351
B35: Agosto | C35: 90.632483 | D35: 125.47553 | E35: 122.47876 | F35: 53.525189 | G35: 72.663174 | H35: 56.849602 | I35: 92.1408 | J35: 75.20813 | K35: 77.238465 | L35: 57.218675 | M35: 38.553526 | N35: 58.810634 | O35: 218.91005
B36: Septiembre | C36: 76.45454 | D36: 113.18691 | E36: 103.88205 | F36: 42.259493 | G36: 58.573763 | H36: 49.217621 | I36: 79.091539 | J36: 53.871805 | K36: 63.536051 | L36: 46.576474 | M36: 30.710565 | N36: 48.732673 | O36: 186.10911
B37: Octubre | C37: 64.150251 | D37: 102.34082 | E37: 87.545303 | F37: 31.503417 | G37: 44.644047 | H37: 42.636403 | I37: 69.28261 | J37: 36.771721 | K37: 54.585327 | L37: 36.68621 | M37: 25.566718 | N37: 39.263299 | O37: 151.87191
B38: Noviembre | C38: 53.596945 | D38: 90.258643 | E38: 72.491918 | F38: 24.997703 | G38: 35.747615 | H38: 38.150077 | I38: 61.067841 | J38: 23.531224 | K38: 40.867616 | L38: 30.307986 | M38: 20.607184 | N38: 30.292908 | O38: 125.29286
B39: Diciembre | C39: 44.166439 | D39: 80.488825 | E39: 57.903132 | F39: 19.007293 | G39: 28.114343 | H39: 32.45758 | I39: 53.481228 | J39: 13.728299 | K39: 31.20463 | L39: 23.361437 | M39: 16.343929 | N39: 22.260445 | O39: 97.592344
A40: 2023(p) | B40: Enero | C40: 38.178412 | D40: 76.946335 | E40: 48.823 | F40: 13.083872 | G40: 23.174469 | H40: 27.080756 | I40: 47.696093 | J40: 5.7715797 | K40: 28.008429 | L40: 18.947589 | M40: 12.34222 | N40: 17.073277 | O40: 84.808484
B41: Febrero | C41: 33.932743 | D41: 71.054875 | E41: 42.334037 | F41: 10.972394 | G41: 21.641139 | H41: 24.969152 | I41: 43.016594 | J41: -0.040719786 | K41: 24.039601 | L41: 15.973756 | M41: 11.06973 | N41: 14.410124 | O41: 72.56212
B42: Marzo | C42: 28.658732 | D42: 60.764222 | E42: 35.910889 | F42: 10.371697 | G42: 16.644288 | H42: 23.091484 | I42: 37.64436 | J42: -5.6299823 | K42: 20.593968 | L42: 12.370834 | M42: 9.8860172 | N42: 12.052901 | O42: 56.906517
B43: Abril | C43: 21.287787 | D43: 51.477352 | E43: 27.565537 | F43: 5.3545545 | G43: 8.3507263 | H43: 16.149149 | I43: 29.104178 | J43: -11.345362 | K43: 15.766005 | L43: 7.3054416 | M43: 5.0011543 | N43: 5.3951784 | O43: 43.246124
B44: Mayo | C44: 15.598062 | D44: 41.112705 | E44: 21.220644 | F44: 2.6645431 | G44: 3.9862001 | H44: 9.8890386 | I44: 23.567769 | J44: -15.083203 | K44: 9.7111107 | L44: 3.0055263 | M44: 3.5308868 | N44: 3.0025838 | O44: 30.61485
B45: Junio | C45: 11.64932 | D45: 34.702693 | E45: 16.839604 | F45: 0.31115953 | G45: 0.9787368 | H45: 6.4500186 | I45: 18.719443 | J45: -17.88781 | K45: 6.323955 | L45: -0.86488022 | M45: 1.8964726 | N45: 0.12848711 | O45: 19.756322
B47: Fuente: DANE, EMA
B48: (p): Cifra provisional
B49: Nota metodológica: Variación acumulado doce meses: variación porcentual calculada entre los últimos 12 meses hasta el mes de referencia y el mismo período del año anterior Regiones: Bogotá DC, Cartagena, Región Central (Boyacá, Cundinamarca, Huila y Tolima), Región Costa Caribe (Atlántico, Cesar, La Guajira y Magdalena), Región Eje Cafetero (Caldas, Quindío y Risaralda), Antioquia, San Andrés y Providencia, Región Pacífico (Valle del Cauca, Cauca, Nariño y Chocó), Región Santanderes (Santander y Norte de Santander), Llanos Orinoquía (Meta, Casanare, Arauca y Vichada), Región Golfo Morrosquillo y Sabana (Bolívar, Córdoba y Sucre), Región Amazonía (Amazonas, Caquetá, Guainía, Putumayo, Guaviare y Vaupés).
...

Sheet 2.1 V.A Per.categ
L4: Inicio
A6: ENCUESTA MENSUAL DE ALOJAMIENTO - EMA
A9: 2.1 Variaciones anuales del personal total y por categoría
A10: Total nacional y 12 regiones
A11: ='1.1 V.A Ing.real'!A12 -> Enero 2020 - junio 2023
A13: Año | B13: Meses | C13: Total nacional | F13: Bogotá D.C. | I13: Cartagena | L13: Central | O13: Caribe | R13: Eje Cafetero | U13: Antioquia | X13: San Andrés y Providencia | AA13: Pacífico | AD13: Santanderes | AG13: Llanos Orinoquía | AJ13: Golfo de Morrosquillo y Sabana | AM13: Amazonía
C14: Total del personal | D14: Personal permanente | E14: Resto de personal | F14: Total del personal | G14: Personal permanente | H14: Resto de personal | I14: Total del personal | J14: Personal permanente | K14: Resto de personal | L14: Total del personal | M14: Personal permanente | N14: Resto de personal | O14: Total del personal | P14: Personal permanente | Q14: Resto de personal | R14: Total del personal | S14: Personal permanente | T14: Resto de personal | U14: Total del personal | V14: Personal permanente | W14: Resto de personal | X14: Total del personal | Y14: Personal permanente | Z14: Resto de personal | AA14: Total del personal | AB14: Personal permanente | AC14: Resto de personal | AD14: Total del personal | AE14: Personal permanente | AF14: Resto de personal | AG14: Total del personal | AH14: Personal permanente | AI14: Resto de personal | AJ14: Total del personal | AK14: Personal permanente | AL14: Resto de personal | AM14: Total del personal | AN14: Personal permanente | AO14: Resto de personal
A15: 2020(p) | B15: Enero | C15: 2.1820408 | D15: 1.0538161 | E15: 3.6666675 | F15: 1.3476145 | G15: 2.2650545 | H15: -0.44416244 | I15: 3.9930471 | J15: 2.2090602 | K15: 6.4614258 | L15: 1.6286857 | M15: 4.0744566 | N15: -0.70868107 | O15: 4.7674563 | P15: -0.94763238 | Q15: 12.224642 | R15: 4.1703674 | S15: 8.2823025 | T15: 2.362939 | U15: 4.0186164 | V15: 0.90153469 | W15: 8.8948853 | X15: -6.8581622 | Y15: -0.92100287 | Z15: -15.238006 | AA15: 1.9071407 | AB15: -0.087296466 | AC15: 5.0933786 | AD15: 2.4784314 | AE15: -1.0030316 | AF15: 5.5127871 | AG15: -8.2130078 | AH15: -14.400871 | AI15: -2.4307818 | AJ15: 8.3571272 | AK15: -3.5000699 | AL15: 21.408797 | AM15: 0.96618357 | AN15: 11.260054 | AO15: -11.146162
B16: Febrero | C16: 2.4231681 | D16: 0.29471945 | E16: 5.3644895 | F16: 2.044 | G16: 1.4240517 | H16: 3.2363325 | I16: 4.1387457 | J16: 2.3209316 | K16: 6.8077568 | L16: 2.1870988 | M16: 4.3693347 | N16: -0.018698692 | O16: 2.7718323 | P16: -3.333541 | Q16: 11.226286 | R16: 6.6262601 | S16: 4.8020127 | T16: 7.4917485 | U16: 3.968371 | V16: -2.8959359 | W16: 16.511697 | X16: -4.2476602 | Y16: -0.15185351 | Z16: -10.315622 | AA16: 2.0039274 | AB16: 1.3415793 | AC16: 3.0406943 | AD16: 3.7696747 | AE16: 0.65145339 | AF16: 6.5233481 | AG16: -8.1596492 | AH16: -12.222374 | AI16: -4.2927546 | AJ16: 3.7019494 | AK16: -3.5271754 | AL16: 11.456839 | AM16: 2.6666667 | AN16: 13.388735 | AO16: -9.6602972
B17: Marzo | C17: -6.6815922 | D17: -2.9128872 | E17: -11.757737 | F17: -6.257584 | G17: -1.7847118 | H17: -14.59523 | I17: -6.159635 | J17: 1.9250636 | K17: -17.562463 | L17: -5.7614015 | M17: -0.10178239 | N17: -11.371311 | O17: -6.7471244 | P17: -6.3018544 | Q17: -7.3527447 | R17: -6.7589385 | S17: 1.4760228 | T17: -10.728591 | U17: -6.2121916 | V17: -5.9789435 | W17: -6.6101476 | X17: -11.966506 | Y17: -6.7209412 | Z17: -19.388013 | AA17: -6.2135719 | AB17: -1.6038045 | AC17: -13.251808 | AD17: -4.2542596 | AE17: -8.7323837 | AF17: -0.2916527 | AG17: -12.079414 | AH17: -16.314396 | AI17: -8.0627396 | AJ17: -5.0819136 | AK17: -4.3101016 | AL17: -5.9012956 | AM17: -5.0756467 | AN17: 3.240324 | AO17: -14.925373
B18: Abril | C18: -24.498344 | D18: -10.885298 | E18: -42.838984 | F18: -24.642457 | G18: -12.962374 | H18: -47.007496 | I18: -24.957286 | J18: -6.6133298 | K18: -51.530412 | L18: -21.722348 | M18: -6.9380673 | N18: -36.284894 | O18: -24.666247 | P18: -8.3551536 | Q18: -46.104866 | R18: -29.465395 | S18: -20.548965 | T18: -33.673923 | U18: -26.755048 | V18: -13.651547 | W18: -48.660175 | X18: -20.078478 | Y18: -11.368726 | Z18: -32.511059 | AA18: -21.174448 | AB18: -8.3531042 | AC18: -41.412265 | AD18: -24.846092 | AE18: -14.538003 | AF18: -33.869284 | AG18: -32.84946 | AH18: -27.004082 | AI18: -38.059208 | AJ18: -16.614008 | AK18: -10.142776 | AL18: -23.143856 | AM18: -22.516226 | AN18: -5.1959891 | AO18: -43.487859
B19: Mayo | C19: -30.876675 | D19: -18.678428 | E19: -47.667875 | F19: -33.495014 | G19: -22.085224 | H19: -54.881618 | I19: -31.804577 | J19: -15.443074 | K19: -55.658881 | L19: -24.653736 | M19: -11.978461 | N19: -37.549053 | O19: -30.05295 | P19: -17.204483 | Q19: -47.991938 | R19: -36.76747 | S19: -26.031963 | T19: -41.821507 | U19: -35.371422 | V19: -25.69167 | W19: -52.590741 | X19: -21.289199 | Y19: -11.805865 | Z19: -35.597095 | AA19: -25.807904 | AB19: -10.615484 | AC19: -49.07099 | AD19: -33.275908 | AE19: -22.302944 | AF19: -42.890597 | AG19: -31.832637 | AH19: -29.670382 | AI19: -34.017176 | AJ19: -24.953202 | AK19: -23.194131 | AL19: -26.717125 | AM19: -31.065089 | AN19: -13.26624 | AO19: -51.871658
B20: Junio | C20: -37.834913 | D20: -25.232823 | E20: -55.05713 | F20: -41.753682 | G20: -31.430353 | H20: -61.228103 | I20: -38.637938 | J20: -23.925704 | K20: -60.916844 | L20: -32.248954 | M20: -15.330585 | N20: -48.353468 | O20: -38.590749 | P20: -25.743467 | Q20: -56.776192 | R20: -45.810029 | S20: -34.783576 | T20: -50.770371 | U20: -41.667557 | V20: -31.376664 | W20: -58.76255 | X20: -26.612369 | Y20: -12.697849 | Z20: -48.326751 | AA20: -30.150436 | AB20: -15.901234 | AC20: -52.23885 | AD20: -41.075047 | AE20: -23.557343 | AF20: -55.771146 | AG20: -30.687704 | AH20: -26.421975 | AI20: -35.02262 | AJ20: -28.069136 | AK20: -24.201301 | AL20: -31.830366 | AM20: -32.070831 | AN20: -13.394495 | AO20: -53.658537
B21: Julio | C21: -42.754981 | D21: -29.355282 | E21: -60.391608 | F21: -48.665213 | G21: -35.029565 | H21: -71.190214 | I21: -41.239708 | J21: -26.221034 | K21: -63.076385 | L21: -33.639287 | M21: -15.583307 | N21: -50.512088 | O21: -42.722827 | P21: -30.015612 | Q21: -60.202171 | R21: -48.863135 | S21: -40.037034 | T21: -53.095656 | U21: -47.477632 | V21: -37.315057 | W21: -63.770329 | X21: -37.363299 | Y21: -17.332057 | Z21: -69.321492 | AA21: -36.325532 | AB21: -22.495676 | AC21: -57.441314 | AD21: -43.608563 | AE21: -28.58884 | AF21: -56.341621 | AG21: -33.633769 | AH21: -34.217172 | AI21: -33.060272 | AJ21: -36.08776 | AK21: -33.249016 | AL21: -38.886195 | AM21: -36.194213 | AN21: -25.760286 | AO21: -48.859935
B22: Agosto | C22: -45.063806 | D22: -32.431459 | E22: -61.756438 | F22: -50.089873 | G22: -39.197064 | H22: -68.779625 | I22: -42.91999 | J22: -28.499882 | K22: -64.286882 | L22: -34.97265 | M22: -17.18137 | N22: -51.731077 | O22: -47.041655 | P22: -34.854973 | Q22: -63.540013 | R22: -50.802085 | S22: -41.366143 | T22: -55.240157 | U22: -49.17185 | V22: -39.645508 | W22: -64.402856 | X22: -37.58111 | Y22: -16.515451 | Z22: -71.011084 | AA22: -42.646807 | AB22: -30.237008 | AC22: -61.525824 | AD22: -46.191578 | AE22: -30.627545 | AF22: -59.125265 | AG22: -35.925346 | AH22: -30.710792 | AI22: -40.843066 | AJ22: -38.52479 | AK22: -35.637848 | AL22: -41.353383 | AM22: -41.863834 | AN22: -25.670841 | AO22: -60.860441
B23: Septiembre | C23: -44.663654 | D23: -34.006728 | E23: -58.813629 | F23: -52.580842 | G23: -41.837274 | H23: -70.786491 | I23: -42.870429 | J23: -28.855149 | K23: -63.915933 | L23: -34.609272 | M23: -20.368195 | N23: -48.464974 | O23: -44.637627 | P23: -37.182295 | Q23: -54.676603 | R23: -42.859961 | S23: -40.721257 | T23: -43.930263 | U23: -47.307908 | V23: -39.51743 | W23: -59.513607 | X23: -37.544089 | Y23: -16.214632 | Z23: -71.748798 | AA23: -44.484218 | AB23: -36.014013 | AC23: -57.329291 | AD23: -44.674939 | AE23: -29.215746 | AF23: -57.539921 | AG23: -34.669051 | AH23: -33.626889 | AI23: -35.64395 | AJ23: -40.335752 | AK23: -34.937179 | AL23: -45.542169 | AM23: -40.970221 | AN23: -22.232223 | AO23: -62.409887
B24: Octubre | C24: -41.562527 | D24: -34.904023 | E24: -50.246476 | F24: -53.375589 | G24: -44.484784 | H24: -68.681104 | I24: -40.592699 | J24: -29.59231 | K24: -56.515146 | L24: -28.976223 | M24: -18.855004 | N24: -38.499804 | O24: -38.207338 | P24: -36.231427 | Q24: -40.717883 | R24: -35.738279 | S24: -41.056162 | T24: -33.064449 | U24: -44.75881 | V24: -39.360374 | W24: -53.084694 | X24: -30.59494 | Y24: -16.640488 | Z24: -53.024128 | AA24: -43.242034 | AB24: -37.290357 | AC24: -52.324638 | AD24: -45.047476 | AE24: -34.685405 | AF24: -53.470588 | AG24: -26.520706 | AH24: -32.321619 | AI24: -21.276596 | AJ24: -34.420577 | AK24: -36.907449 | AL24: -32.042895 | AM24: -36.131211 | AN24: -29.133155 | AO24: -44.339623
B25: Noviembre | C25: -40.26556 | D25: -35.457133 | E25: -46.526781 | F25: -54.095795 | G25: -46.483855 | H25: -66.942863 | I25: -40.158499 | J25: -30.203131 | K25: -54.45278 | L25: -27.221642 | M25: -19.630652 | N25: -34.639449 | O25: -36.049743 | P25: -39.536936 | Q25: -31.497808 | R25: -32.411778 | S25: -35.797462 | T25: -30.775681 | U25: -41.898783 | V25: -37.146354 | W25: -49.195324 | X25: -28.906131 | Y25: -15.735175 | Z25: -50.293164 | AA25: -40.872975 | AB25: -37.099118 | AC25: -46.668986 | AD25: -41.976376 | AE25: -32.554428 | AF25: -49.562531 | AG25: -27.634752 | AH25: -32.659933 | AI25: -23.302644 | AJ25: -32.289223 | AK25: -38.856368 | AL25: -26.148198 | AM25: -34.608121 | AN25: -33.611343 | AO25: -35.908596
B26: Diciembre | C26: -38.007281 | D26: -34.232455 | E26: -42.699972 | F26: -53.062108 | G26: -47.414005 | H26: -62.894731 | I26: -37.76886 | J26: -29.592864 | K26: -48.925625 | L26: -28.44845 | M26: -20.822387 | N26: -35.495798 | O26: -30.30976 | P26: -36.798341 | Q26: -22.6247 | R26: -31.703556 | S26: -36.16794 | T26: -29.620578 | U26: -38.657227 | V26: -33.003385 | W26: -46.362849 | X26: -25.50444 | Y26: -13.44255 | Z26: -45.507949 | AA26: -40.291662 | AB26: -35.872259 | AC26: -46.716745 | AD26: -39.277494 | AE26: -29.113113 | AF26: -47.344961 | AG26: -28.75547 | AH26: -25.943421 | AI26: -30.878032 | AJ26: -31.858407 | AK26: -39.350384 | AL26: -24.856785 | AM26: -28.943489 | AN26: -30.099502 | AO26: -27.261761
A27: 2021(p) | B27: Enero | C27: -37.594248 | D27: -35.106671 | E27: -40.785138 | F27: -53.149096 | G27: -49.467861 | H27: -60.534264 | I27: -37.228732 | J27: -29.685621 | K27: -47.248734 | L27: -28.588169 | M27: -21.994938 | N27: -35.192704 | O27: -29.052773 | P27: -33.705219 | Q27: -23.694682 | R27: -32.815785 | S27: -36.33334 | T27: -31.180211 | U27: -40.114058 | V27: -37.803486 | W27: -43.463321 | X27: -22.357826 | Y27: -11.201922 | Z27: -40.763104 | AA27: -41.436458 | AB27: -38.578863 | AC27: -45.776598 | AD27: -38.144803 | AE27: -31.635855 | AF27: -43.467508 | AG27: -29.650523 | AH27: -32.115042 | AI27: -27.630096 | AJ27: -28.232154 | AK27: -36.885543 | AL27: -20.661262 | AM27: -27.416268 | AN27: -24.899598 | AO27: -31.12426
B28: Febrero | C28: -38.017089 | D28: -35.026285 | E28: -41.95124 | F28: -54.564039 | G28: -48.927418 | H28: -65.214519 | I28: -40.471871 | J28: -32.272727 | K28: -52.004573 | L28: -25.427779 | M28: -19.686791 | N28: -31.485436 | O28: -29.257911 | P28: -32.759215 | Q28: -25.044134 | R28: -32.518205 | S28: -41.388164 | T28: -28.415279 | U28: -39.812668 | V28: -38.025126 | W28: -42.534994 | X28: -22.634364 | Y28: -11.404097 | Z28: -41.157592 | AA28: -39.531243 | AB28: -37.694412 | AC28: -42.359005 | AD28: -36.237798 | AE28: -29.87888 | AF28: -41.543758 | AG28: -27.063789 | AH28: -28.552209 | AI28: -25.764488 | AJ28: -20.009838 | AK28: -18.017952 | AL28: -21.859331 | AM28: -31.216931 | AN28: -35.423453 | AO28: -25.146886
B29: Marzo | C29: -30.595417 | D29: -32.595959 | E29: -27.630761 | F29: -50.936187 | G29: -47.386843 | H29: -58.544739 | I29: -31.632872 | J29: -32.042793 | K29: -30.918038 | L29: -19.318775 | M29: -17.239127 | N29: -21.642271 | O29: -19.813529 | P29: -30.258262 | Q29: -5.4463089 | R29: -21.067767 | S29: -39.734086 | T29: -10.839532 | U29: -32.891462 | V29: -35.185136 | W29: -28.951661 | X29: -12.9099 | Y29: -2.5631804 | Z29: -29.848871 | AA29: -32.890493 | AB29: -34.913709 | AC29: -29.386649 | AD29: -26.910503 | AE29: -22.825952 | AF29: -30.218875 | AG29: -18.016049 | AH29: -22.3869 | AI29: -14.242584 | AJ29: -10.332951 | AK29: -16.373019 | AL29: -3.8121767 | AM29: -24.37018 | AN29: -29.642546 | AO29: -16.79198
B30: Abril | C30: -15.303482 | D30: -27.547733 | E30: 10.414734 | F30: -40.587979 | G30: -42.884886 | H30: -33.364278 | I30: -13.330706 | J30: -26.066021 | K30: 22.213998 | L30: -5.0529388 | M30: -13.926411 | N30: 7.7132221 | O30: -4.166298 | P30: -28.894473 | Q30: 51.100498 | R30: 4.2259968 | S30: -23.866329 | T30: 20.109347 | U30: -15.689174 | V30: -30.251566 | W30: 25.25492 | X30: -2.4165765 | Y30: 4.6372151 | Z30: -15.639652 | AA30: -20.621444 | AB30: -31.503956 | AC30: 6.2487216 | AD30: -6.8934398 | AE30: -18.314587 | AF30: 6.0265325 | AG30: 3.3793463 | AH30: -10.956466 | AI30: 18.436686 | AJ30: -1.0770999 | AK30: -8.6289625 | AL30: 7.8322197 | AM30: -8.7628866 | AN30: -24.326923 | AO30: 22.851562
B31: Mayo | C31: -9.8272296 | D31: -21.192143 | E31: 14.482928 | F31: -34.703733 | G31: -36.251752 | H31: -29.692937 | I31: -7.3930935 | J31: -19.74913 | K31: 26.959955 | L31: -2.1640544 | M31: -9.2215965 | N31: 7.9558878 | O31: 2.5898444 | P31: -21.271933 | Q31: 55.62765 | R31: 4.8428369 | S31: -13.438181 | T31: 15.784867 | U31: -6.0182262 | V31: -20.442709 | W31: 34.200316 | X31: -0.20601355 | Y31: 2.2967305 | Z31: -5.3769054 | AA31: -21.252897 | AB31: -30.121665 | AC31: 2.5813113 | AD31: 6.059648 | AE31: -10.459765 | AF31: 25.752238 | AG31: 2.5345542 | AH31: -6.3116901 | AI31: 12.060738 | AJ31: 7.5913027 | AK31: 5.9331374 | AL31: 9.3339768 | AM31: -0.35765379 | AN31: -17.510549 | AO31: 35.777778
B32: Junio | C32: 3.4247937 | D32: -14.450886 | E32: 44.06531 | F32: -22.166135 | G32: -27.315127 | H32: -4.9877671 | I32: 7.7341733 | J32: -11.28943 | K32: 63.807501 | L32: 7.8385343 | M32: -6.0779561 | N32: 29.555756 | O32: 19.693678 | P32: -14.674475 | Q32: 103.26946 | R32: 27.199633 | S32: 1.6720696 | T32: 42.412657 | U32: 8.0168026 | V32: -13.551827 | W32: 67.64044 | X32: 10.895415 | Y32: 4.9609683 | Z32: 26.541968 | AA32: -15.30785 | AB32: -26.693773 | AC32: 15.770434 | AD32: 22.042038 | AE32: -6.5771678 | AF32: 63.53864 | AG32: 7.321693 | AH32: -11.70829 | AI32: 29.220058 | AJ32: 10.551303 | AK32: 6.5087654 | AL32: 14.922363 | AM32: 2.7516293 | AN32: -18.855932 | AO32: 49.427918
B33: Julio | C33: 16.90318 | D33: -7.4167233 | E33: 73.995125 | F33: -11.801465 | G33: -20.95605 | H33: 22.302385 | I33: 19.556941 | J33: -6.1484662 | K33: 94.23754 | L33: 13.023565 | M33: -2.9487887 | N33: 38.483909 | O33: 33.148415 | P33: -6.9900048 | Q33: 130.23893 | R33: 44.719944 | S33: 0.73474603 | T33: 71.685344 | U33: 25.970834 | V33: -4.3475465 | W33: 110.07047 | X33: 34.197933 | Y33: 12.311795 | Z33: 128.28856 | AA33: 0.027051886 | AB33: -16.990339 | AC33: 47.344379 | AD33: 34.366284 | AE33: 2.0641101 | AF33: 79.158346 | AG33: 22.170665 | AH33: 5.3205374 | AI33: 38.448417 | AJ33: 27.28265 | AK33: 18.778947 | AL33: 36.438853 | AM33: 15.603382 | AN33: -5.6626506 | AO33: 53.078556
B34: Agosto | C34: 25.46588 | D34: -0.71916447 | E34: 86.599524 | F34: -3.8197223 | G34: -13.207803 | H34: 27.551175 | I34: 26.901841 | J34: -1.7876771 | K34: 112.01076 | L34: 17.866104 | M34: 1.3986979 | N34: 44.480195 | O34: 46.964752 | P34: 0.54609613 | Q34: 159.24737 | R34: 51.785493 | S34: 8.0463097 | T34: 78.734313 | U34: 33.59084 | V34: 3.3338349 | W34: 115.6114 | X34: 39.017392 | Y34: 14.811427 | Z34: 149.64347 | AA34: 14.422387 | AB34: -4.5895229 | AC34: 66.866432 | AD34: 42.819542 | AE34: 6.0014263 | AF34: 94.746615 | AG34: 28.595641 | AH34: 8.0579754 | AI34: 51.281626 | AJ34: 33.767853 | AK34: 25.246117 | AL34: 42.931075 | AM34: 27.740864 | AN34: 8.543923 | AO34: 70.509383
B35: Septiembre | C35: 28.326417 | D35: 3.8142023 | E35: 80.476192 | F35: 6.3174577 | G35: -6.6242369 | H35: 49.980081 | I35: 29.349019 | J35: -0.40643458 | K35: 117.44419 | L35: 22.406015 | M35: 7.3055043 | N35: 45.107874 | O35: 45.682728 | P35: 8.1531693 | Q35: 115.72423 | R35: 39.038376 | S35: 10.602659 | T35: 54.083307 | U35: 27.945309 | V35: 4.0497345 | W35: 83.874325 | X35: 44.431598 | Y35: 15.580012 | Z35: 181.64832 | AA35: 20.623308 | AB35: 5.5909307 | AC35: 54.807497 | AD35: 42.892348 | AE35: 6.350314 | AF35: 93.588025 | AG35: 29.746713 | AH35: 21.975347 | AI35: 37.244357 | AJ35: 42.663299 | AK35: 27.166996 | AL35: 60.518331 | AM35: 25.874695 | AN35: 8.2175926 | AO35: 67.671233
B36: Octubre | C36: 26.168766 | D36: 8.6940604 | E36: 55.986918 | F36: 16.438076 | G36: 4.774444 | H36: 52.029576 | I36: 27.43226 | J36: 0.81080565 | K36: 89.822349 | L36: 15.806972 | M36: 8.3211375 | N36: 25.100763 | O36: 32.224143 | P36: 11.225248 | Q36: 60.924021 | R36: 25.57365 | S36: 13.865281 | T36: 30.757748 | U36: 27.70682 | V36: 6.8606775 | W36: 69.262471 | X36: 34.19432 | Y36: 17.294751 | Z36: 82.395393 | AA36: 22.56995 | AB36: 8.7957354 | AC36: 50.218872 | AD36: 51.665734 | AE36: 20.700916 | AF36: 86.99847 | AG36: 21.387283 | AH36: 31.290323 | AI36: 13.69084 | AJ36: 35.757098 | AK36: 37.701252 | AL36: 34.031362 | AM36: 19.637462 | AN36: 18.537201 | AO36: 21.280603
B37: Noviembre | C37: 26.545561 | D37: 10.7883 | E37: 51.311145 | F37: 20.263214 | G37: 7.4168113 | H37: 55.36343 | I37: 29.980875 | J37: 2.7317691 | K37: 89.936693 | L37: 14.655241 | M37: 7.6995701 | N37: 23.01302 | O37: 33.781571 | P37: 23.387896 | Q37: 45.756555 | R37: 20.242666 | S37: 7.378704 | T37: 26.008085 | U37: 24.4046 | V37: 5.9758063 | W37: 59.409197 | X37: 29.810039 | Y37: 13.978495 | Z37: 73.389992 | AA37: 27.829231 | AB37: 10.551271 | AC37: 59.126984 | AD37: 50.960921 | AE37: 18.65247 | AF37: 85.746346 | AG37: 16.788395 | AH37: 34.890625 | AI37: 3.0867483 | AJ37: 32.698186 | AK37: 44.576766 | AL37: 23.501763 | AM37: 16.750903 | AN37: 20.728643 | AO37: 11.375212
B38: Diciembre | C38: 26.165466 | D38: 11.344927 | E38: 47.312318 | F38: 24.207469 | G38: 11.951381 | H38: 54.445475 | I38: 34.722633 | J38: 4.4208074 | K38: 91.723321 | L38: 16.094753 | M38: 7.4512651 | N38: 25.899328 | O38: 24.224861 | P38: 21.884388 | Q38: 26.489126 | R38: 19.707785 | S38: 11.037457 | T38: 23.376818 | U38: 25.099524 | V38: 7.372934 | W38: 55.276546 | X38: 24.015573 | Y38: 9.2229782 | Z38: 62.983425 | AA38: 26.569299 | AB38: 10.396908 | AC38: 54.866566 | AD38: 45.014832 | AE38: 11.894507 | AF38: 80.404522 | AG38: 19.226551 | AH38: 29.82407 | AI38: 10.656388 | AJ38: 36.203796 | AK38: 48.640799 | AL38: 26.822643 | AM38: 12.30982 | AN38: 13.16726 | AO38: 11.111111
A39: 2022(p) | B39: Enero | C39: 26.008799 | D39: 13.862786 | E39: 43.082917 | F39: 25.92006 | G39: 19.404923 | H39: 42.655526 | I39: 33.805193 | J39: 5.6674368 | K39: 83.626832 | L39: 15.960227 | M39: 4.2976707 | N39: 30.021889 | O39: 22.624649 | P39: 19.67164 | Q39: 25.579381 | R39: 21.816378 | S39: 8.971512 | T39: 27.341703 | U39: 28.331496 | V39: 13.587372 | W39: 51.84322 | X39: 20.644952 | Y39: 7.8006473 | Z39: 52.410731 | AA39: 22.730917 | AB39: 15.378668 | AC39: 35.379868 | AD39: 43.564574 | AE39: 25.886191 | AF39: 61.046702 | AG39: 26.276159 | AH39: 35.370426 | AI39: 19.282666 | AJ39: 28.153832 | AK39: 48.497362 | AL39: 13.994891 | AM39: 12.656559 | AN39: 6.4171123 | AO39: 22.680412
B40: Febrero | C40: 26.961796 | D40: 15.5902 | E40: 43.656594 | F40: 33.978628 | G40: 19.601052 | H40: 73.865117 | I40: 37.597701 | J40: 10.858254 | K40: 90.671326 | L40: 13.897746 | M40: 4.8595044 | N40: 24.638319 | O40: 23.820505 | P40: 23.550998 | Q40: 24.111468 | R40: 17.485863 | S40: 4.8721419 | T40: 22.263138 | U40: 28.988102 | V40: 16.541746 | W40: 49.430804 | X40: 18.839536 | Y40: 9.2065736 | Z40: 42.762209 | AA40: 21.09856 | AB40: 14.673462 | AC40: 31.790313 | AD40: 39.327663 | AE40: 24.349563 | AF40: 54.31952 | AG40: 20.408028 | AH40: 29.88847 | AI40: 12.442957 | AJ40: 21.488184 | AK40: 24.54157 | AL40: 18.513701 | AM40: 21.258741 | AN40: 24.968474 | AO40: 16.640502
B41: Marzo | C41: 27.023274 | D41: 17.644497 | E41: 39.923598 | F41: 44.738133 | G41: 26.669886 | H41: 93.895052 | I41: 34.208997 | J41: 12.071696 | K41: 72.184214 | L41: 15.248716 | M41: 6.9962126 | N41: 24.561404 | O41: 21.323484 | P41: 22.937665 | Q41: 19.685756 | R41: 18.268794 | S41: 9.2966711 | T41: 21.591842 | U41: 27.444401 | V41: 17.086093 | W41: 43.675656 | X41: 13.124701 | Y41: 6.7278588 | Z41: 27.670528 | AA41: 23.160385 | AB41: 16.438686 | AC41: 33.890009 | AD41: 36.701655 | AE41: 26.285499 | AF41: 46.032281 | AG41: 17.972206 | AH41: 34.501502 | AI41: 5.0572786 | AJ41: 18.348271 | AK41: 29.813117 | AL41: 7.5872911 | AM41: 18.626784 | AN41: 26.146221 | AO41: 9.4879518
B42: Abril | C42: 29.966624 | D42: 19.223402 | E42: 44.713606 | F42: 48.77185 | G42: 31.417458 | H42: 95.552867 | I42: 36.907614 | J42: 12.65015 | K42: 77.86514 | L42: 20.006383 | M42: 8.2268688 | N42: 32.986329 | O42: 27.539652 | P42: 25.206537 | Q42: 29.993489 | R42: 21.513404 | S42: 12.075267 | T42: 24.895927 | U42: 32.763398 | V42: 20.025702 | W42: 52.706334 | X42: 9.832347 | Y42: 4.4707317 | Z42: 22.299098 | AA42: 24.758598 | AB42: 16.4782 | AC42: 37.939166 | AD42: 27.149816 | AE42: 22.479586 | AF42: 31.220057 | AG42: 23.288405 | AH42: 39.390479 | AI42: 10.573184 | AJ42: 21.681873 | AK42: 26.403237 | AL42: 16.962134 | AM42: 25.423729 | AN42: 35.70521 | AO42: 12.559618
B43: Mayo | C43: 35.322228 | D43: 21.448356 | E43: 55.702957 | F43: 57.383499 | G43: 31.73147 | H43: 132.67076 | I43: 43.606736 | J43: 18.35442 | K43: 87.985001 | L43: 21.844759 | M43: 10.143483 | N43: 35.507045 | O43: 30.682804 | P43: 26.200713 | Q43: 35.722523 | R43: 33.922005 | S43: 7.0881887 | T43: 45.92956 | U43: 35.993525 | V43: 21.826472 | W43: 59.410568 | X43: 8.646546 | Y43: 6.7997135 | Z43: 12.771709 | AA43: 37.326406 | AB43: 20.111186 | AC43: 68.841917 | AD43: 29.429153 | AE43: 27.821664 | AF43: 30.793607 | AG43: 32.416556 | AH43: 39.310543 | AI43: 26.209834 | AJ43: 21.621976 | AK43: 25.880007 | AL43: 17.28613 | AM43: 26.058866 | AN43: 34.015345 | AO43: 15.875614
B44: Junio | C44: 32.998161 | D44: 22.854704 | E44: 46.66308 | F44: 57.849666 | G44: 36.003605 | H44: 113.6064 | I44: 40.418196 | J44: 19.229397 | K44: 74.241146 | L44: 21.586257 | M44: 11.761914 | N44: 32.422183 | O44: 28.129122 | P44: 27.311937 | Q44: 28.963286 | R44: 26.533434 | S44: 7.481121 | T44: 34.63944 | U44: 31.769797 | V44: 21.88176 | W44: 45.86538 | X44: 6.6480475 | Y44: 5.5550172 | Z44: 9.0384106 | AA44: 34.07035 | AB44: 22.357736 | AC44: 54.31386 | AD44: 29.560803 | AE44: 27.495979 | AF44: 31.271096 | AG44: 25.048936 | AH44: 44.448495 | AI44: 9.7959418 | AJ44: 23.729185 | AK44: 27.228156 | AL44: 20.222846 | AM44: 21.775899 | AN44: 34.725849 | AO44: 6.5849923
B45: Julio | C45: 29.647392 | D45: 23.083199 | E45: 37.820067 | F45: 55.147427 | G45: 37.357915 | H45: 97.978854 | I45: 35.082273 | J45: 19.525999 | K45: 56.919482 | L45: 21.568243 | M45: 9.523185 | N45: 34.753695 | O45: 25.287257 | P45: 27.024001 | Q45: 23.590173 | R45: 21.330562 | S45: 17.142354 | T45: 22.837081 | U45: 27.981875 | V45: 24.656256 | W45: 32.182285 | X45: 5.067331 | Y45: 4.3047628 | Z45: 6.6801927 | AA45: 29.161258 | AB45: 18.234721 | AC45: 46.277359 | AD45: 23.04428 | AE45: 24.895485 | AF45: 21.581902 | AG45: 26.811796 | AH45: 47.426739 | AI45: 11.662292 | AJ45: 21.70054 | AK45: 24.920241 | AL45: 18.682505 | AM45: 17.68617 | AN45: 41.890166 | AO45: -8.5991678
B46: Agosto | C46: 26.858412 | D46: 21.193953 | E46: 33.894646 | F46: 45.440239 | G46: 33.957964 | H46: 71.548278 | I46: 32.471823 | J46: 17.494412 | K46: 53.054254 | L46: 19.155864 | M46: 10.439761 | N46: 29.042142 | O46: 24.086216 | P46: 28.766186 | Q46: 19.695717 | R46: 19.401886 | S46: 11.716448 | T46: 22.264349 | U46: 25.878723 | V46: 20.355958 | W46: 33.05376 | X46: 2.9498619 | Y46: 2.3500469 | Z46: 4.2105782 | AA46: 27.867196 | AB46: 15.634873 | AC46: 47.160494 | AD46: 23.59644 | AE46: 25.208301 | AF46: 22.359064 | AG46: 26.389996 | AH46: 43.741747 | AI46: 12.699457 | AJ46: 21.023642 | AK46: 24.331878 | AL46: 17.906517 | AM46: 21.651495 | AN46: 29.822616 | AO46: 10.062893
B47: Septiembre | C47: 24.606073 | D47: 20.092699 | E47: 30.129492 | F47: 43.112562 | G47: 32.996118 | H47: 64.361985 | I47: 31.09483 | J47: 18.717303 | K47: 47.879117 | L47: 18.644269 | M47: 10.790652 | N47: 27.375401 | O47: 20.314237 | P47: 25.38645 | Q47: 15.568324 | R47: 17.186849 | S47: 9.7119289 | T47: 20.025699 | U47: 25.670088 | V47: 20.442671 | W47: 32.593605 | X47: -0.1354659 | Y47: 0.80553163 | Z47: -1.9720102 | AA47: 23.816948 | AB47: 14.182658 | AC47: 38.760435 | AD47: 20.83961 | AE47: 22.890168 | AF47: 19.276784 | AG47: 19.08186 | AH47: 25.09655 | AI47: 13.92461 | AJ47: 18.977231 | AK47: 27.385677 | AL47: 11.301882 | AM47: 18.293471 | AN47: 23.636364 | AO47: 10.130719
...

Sheet 2.2 V.A.C Per.categ
L4: Inicio
A6: ENCUESTA MENSUAL DE ALOJAMIENTO - EMA
A9: 2.2 Variaciones año corrido del personal total y por categoría
A10: Total nacional y 12 regiones
A11: ='1.1 V.A Ing.real'!A12 -> Enero 2020 - junio 2023
A13: Año | B13: Meses | C13: Total nacional | F13: Bogotá D.C. | I13: Cartagena | L13: Central | O13: Caribe | R13: Eje Cafetero | U13: Antioquia | X13: San Andrés y Providencia | AA13: Pacífico | AD13: Santanderes | AG13: Llanos Orinoquía | AJ13: Golfo de Morrosquillo y Sabana | AM13: Amazonía
C14: Total del personal | D14: Personal permanente | E14: Resto de personal | F14: Total del personal | G14: Personal permanente | H14: Resto de personal | I14: Total del personal | J14: Personal permanente | K14: Resto de personal | L14: Total del personal | M14: Personal permanente | N14: Resto de personal | O14: Total del personal | P14: Personal permanente | Q14: Resto de personal | R14: Total del personal | S14: Personal permanente | T14: Resto de personal | U14: Total del personal | V14: Personal permanente | W14: Resto de personal | X14: Total del personal | Y14: Personal permanente | Z14: Resto de personal | AA14: Total del personal | AB14: Personal permanente | AC14: Resto de personal | AD14: Total del personal | AE14: Personal permanente | AF14: Resto de personal | AG14: Total del personal | AH14: Personal permanente | AI14: Resto de personal | AJ14: Total del personal | AK14: Personal permanente | AL14: Resto de personal | AM14: Total del personal | AN14: Personal permanente | AO14: Resto de personal
A15: 2020(p) | B15: Enero | C15: 2.1820408 | D15: 1.0538161 | E15: 3.6666675 | F15: 1.3476145 | G15: 2.2650545 | H15: -0.44416244 | I15: 3.9930471 | J15: 2.2090602 | K15: 6.4614258 | L15: 1.6286857 | M15: 4.0744566 | N15: -0.70868107 | O15: 4.7674563 | P15: -0.94763238 | Q15: 12.224642 | R15: 4.1703674 | S15: 8.2823025 | T15: 2.362939 | U15: 4.0186164 | V15: 0.90153469 | W15: 8.8948853 | X15: -6.8581622 | Y15: -0.92100287 | Z15: -15.238006 | AA15: 1.9071407 | AB15: -0.087296466 | AC15: 5.0933786 | AD15: 2.4784314 | AE15: -1.0030316 | AF15: 5.5127871 | AG15: -8.2130078 | AH15: -14.400871 | AI15: -2.4307818 | AJ15: 8.3571272 | AK15: -3.5000699 | AL15: 21.408797 | AM15: 0.96618357 | AN15: 11.260054 | AO15: -11.146162
B16: Febrero | C16: 2.3014184 | D16: 0.67404662 | E16: 4.4953009 | F16: 1.6994358 | G16: 1.841269 | H16: 1.4245749 | I16: 4.0651423 | J16: 2.2651014 | K16: 6.6297796 | L16: 1.9000322 | M16: 4.2198288 | N16: -0.37819035 | O16: 3.7849315 | P16: -2.1374369 | Q16: 11.741616 | R16: 5.3659489 | S16: 6.542424 | T16: 4.8290903 | U16: 3.9938695 | V16: -1.0236225 | W16: 12.460762 | X16: -5.5683278 | Y16: -0.53716107 | Z16: -12.841125 | AA16: 1.9552088 | AB16: 0.6195157 | AC16: 4.067519 | AD16: 3.1160673 | AE16: -0.18312944 | AF16: 6.0102683 | AG16: -8.1870083 | AH16: -13.334223 | AI16: -3.3338925 | AJ16: 6.0241404 | AK16: -3.5135704 | AL16: 16.387883 | AM16: 1.8070818 | AN16: 12.306994 | AO16: -10.406762
B17: Marzo | C17: -0.69896402 | D17: -0.52371083 | E17: -0.93515539 | F17: -0.99624669 | G17: 0.62371707 | H17: -4.0943767 | I17: 0.64648533 | J17: 2.1517263 | K17: -1.4908828 | L17: -0.61630808 | M17: 2.7959806 | N17: -3.9776536 | O17: 0.27656131 | P17: -3.5295019 | Q17: 5.4109713 | R17: 1.4234439 | S17: 4.8532789 | T17: -0.17003289 | U17: 0.55915673 | V17: -2.6957876 | W17: 6.0721566 | X17: -7.7087297 | Y17: -2.5936835 | Z17: -15.049746 | AA17: -0.78580937 | AB17: -0.11970758 | AC17: -1.8268221 | AD17: 0.67227287 | AE17: -3.0265612 | AF17: 3.926394 | AG17: -9.4445621 | AH17: -14.299034 | AI17: -4.8587137 | AJ17: 2.3088514 | AK17: -3.7780484 | AL17: 8.8716602 | AM17: -0.48828125 | AN17: 9.2665258 | AO17: -11.903921
B18: Abril | C18: -6.6831639 | D18: -3.1287992 | E18: -11.47305 | F18: -7.0495416 | G18: -2.8553274 | H18: -15.073348 | I18: -5.7232235 | J18: -0.042317112 | K18: -13.829969 | L18: -5.9037542 | M18: 0.35748924 | N18: -12.071414 | O18: -5.9882667 | P18: -4.7314486 | Q18: -7.6726643 | R18: -6.2320724 | S18: -1.4935658 | T18: -8.4422111 | U18: -6.309519 | V18: -5.4407692 | W18: -7.776105 | X18: -10.774881 | Y18: -4.7651566 | Z18: -19.388353 | AA18: -5.9131883 | AB18: -2.1962556 | AC18: -11.736691 | AD18: -5.7896916 | AE18: -5.9357463 | AF18: -5.6613608 | AG18: -15.306776 | AH18: -17.409426 | AI18: -13.349194 | AJ18: -2.5167254 | AK18: -5.3622322 | AL18: 0.49982282 | AM18: -5.9040137 | AN18: 5.6689342 | AO18: -19.561145
B19: Mayo | C19: -11.521677 | D19: -6.2610277 | E19: -18.641092 | F19: -12.509857 | G19: -6.803629 | H19: -23.380215 | I19: -10.919917 | J19: -3.1325429 | K19: -22.080144 | L19: -9.5907616 | M19: -2.0998395 | N19: -17.016694 | O19: -10.714759 | P19: -7.2154549 | Q19: -15.442308 | R19: -12.264468 | S19: -6.3659036 | T19: -15.020747 | U19: -12.10983 | V19: -9.5448761 | W19: -16.485107 | X19: -12.850936 | Y19: -6.1786719 | Z19: -22.511027 | AA19: -9.9324052 | AB19: -3.8849664 | AC19: -19.363348 | AD19: -11.295917 | AE19: -9.2106651 | AF19: -13.127104 | AG19: -18.404883 | AH19: -19.786498 | AI19: -17.098715 | AJ19: -7.0942684 | AK19: -8.9216818 | AL19: -5.1788771 | AM19: -10.918919 | AN19: 1.9080502 | AO19: -26.027397
B20: Junio | C20: -15.948781 | D20: -9.4639639 | E20: -24.739327 | F20: -17.5032 | G20: -10.996838 | H20: -29.877094 | I20: -15.529985 | J20: -6.6555899 | K20: -28.364639 | L20: -13.444361 | M20: -4.3118757 | N20: -22.43535 | O20: -15.416921 | P20: -10.391978 | Q20: -22.259067 | R20: -17.905375 | S20: -11.041862 | T20: -21.092248 | U20: -17.120748 | V20: -13.215757 | W20: -23.751902 | X20: -15.102107 | Y20: -7.2721112 | Z20: -26.57743 | AA20: -13.344665 | AB20: -5.9090273 | AC20: -24.928735 | AD20: -16.291965 | AE20: -11.568745 | AF20: -20.408074 | AG20: -20.334591 | AH20: -20.861433 | AI20: -19.830831 | AJ20: -10.688418 | AK20: -11.459972 | AL20: -9.8900431 | AM20: -14.44135 | AN20: -0.62187168 | AO20: -30.667854
B21: Julio | C21: -19.823093 | D21: -12.307976 | E21: -29.966896 | F21: -22.13732 | G21: -14.418892 | H21: -36.506817 | I21: -19.191193 | J21: -9.4470085 | K21: -33.294458 | L21: -16.373209 | M21: -5.909701 | N21: -26.596997 | O21: -19.363046 | P21: -13.238322 | Q21: -27.714943 | R21: -22.365391 | S21: -15.29812 | T21: -25.662237 | U21: -21.567104 | V21: -16.680674 | W21: -29.794826 | X21: -18.200697 | Y21: -8.7133356 | Z21: -32.269036 | AA21: -16.663212 | AB21: -8.2880172 | AC21: -29.673038 | AD21: -20.215345 | AE21: -13.982392 | AF21: -25.625674 | AG21: -22.06715 | AH21: -22.622735 | AI21: -21.533987 | AJ21: -14.400938 | AK21: -14.57977 | AL21: -14.217196 | AM21: -17.554573 | AN21: -4.2666321 | AO21: -33.231334
