Workbook
Name _2010: [1]Ingresos!$A$63
Name _2011: [1]Ingresos!$A$75
Name _2012: [1]Ingresos!$A$87
Name _2013: [1]Ingresos!$A$99
Name _2014: [1]Ingresos!$A$111
Name _2015: [1]Ingresos!$A$123
Name _2016: [1]Ingresos!$A$135
Name _fechaActualiza: #REF!
Name _fechaActualiza: #REF!
Name _fechaActualiza: #REF!
Name _fechaActualiza: #REF!
Name _fechaActualiza: #REF!
Name _fechaActualiza: #REF!
Name _fechaActualiza: #REF!
Name _fechaActualiza: #REF!
Name _fechaActualiza: #REF!
Name _fechaActualiza: #REF!
Name _fechaActualiza: #REF!
Name _fechaActualiza: #REF!
Name _fechaActualiza: #REF!
Name _fechaActualiza: #REF!
Name _fechaActualiza: #REF!
Name _fechaActualiza: #REF!
Name _fechaActualiza: #REF!
Name _fechaActualiza: #REF!
Name _FileSalida: #REF!
Name _FileSalida: #REF!
Name _FileSalida: #REF!
Name _FileSalida: #REF!
Name _FileSalida: #REF!
Name _FileSalida: #REF!
Name _FileSalida: #REF!
Name _FileSalida: #REF!
Name _FileSalida: #REF!
Name _FileSalida: #REF!
Name _FileSalida: #REF!
Name _FileSalida: #REF!
Name _FileSalida: #REF!
Name _FileSalida: #REF!
Name _FileSalida: #REF!
Name _FileSalida: #REF!
Name _FileSalida: #REF!
Name _FileSalida: #REF!
Name _um: #REF!
Name _um: #REF!
Name _um: #REF!
Name _um: #REF!
Name _um: #REF!
Name _um: #REF!
Name _um: #REF!
Name _um: #REF!
Name _um: #REF!
Name _um: #REF!
Name _um: #REF!
Name _um: #REF!
Name _um: #REF!
Name _um: #REF!
Name _um: #REF!
Name _um: #REF!
Name _um: #REF!

Sheet Contenido
A3: ENCUESTA MENSUAL DE ALOJAMIENTO - EMA
A5: Contenido
A8: ='1.1 V.A Ing.real'!A10:O10 -> 1.1 Variaciones anuales de los ingresos reales
A9: ='1.2 V.A.C Ing.real'!A10:O10 -> 1.2 Variaciones año corrido de los ingresos reales
A10: 1.3 Variaciones 12 meses de los ingresos reales
A11: ='2.1 V.A Per.categ'!A10:N10 -> 2.1 Variaciones anuales del personal total y por categoría
A12: ='2.2 V.A.C Per.categ'!A10:N10 -> 2.2 Variaciones año corrido del personal total y por categoría
A13: 2.3 Variaciones 12 meses del personal total y por categoría
A14: 3.1 Total variaciones de salarios por región
A15: 3.2 Total variaciones salarios año corrido
A16: 3.3 Total variaciones salarios 12 meses
A17: 4.1 Variaciones bienales de ingresos reales, personal ocupado y salarios
A18: 5.1 Porcentaje de ocupación por escala de habitación
A19: 5.2 Porcentaje de ocupación mensual por región
A20: 5.3 Porcentaje de ocupación año corrido* por región
A21: 5.4 Porcentaje de ocupación 12 meses
A22: 6.1 Distribución porcentual de los motivo de viaje total huéspedes regional mensual
A23: 6.2 Distribución porcentual de los Motivo de viaje total huéspedes regional año corrido
A24: ='6.3 Porc Mens Motivo.viaje.R'!A10:W10 -> 6.3 Distribución porcentual de los motivos de viaje huéspedes residentes, mensual
A25: ='6.4 Porc Mens Motivo.viaje.NR'!A10:W10 -> 6.4 Distribución porcentual de los motivos de viaje huéspedes no residentes, mensual.
A26: 6.5 Distribución porcentual de huéspedes residentes y no residentes
A27: 7.1 Tarifas
A28: 8.1 Índices de oferta y demanda de habitaciones y camas por región total mes.
A29: 9.1 Series índices ingresos nominales, ingresos reales, personal ocupado y salarios reales
A30: 9.2 Series índices de la Muestra Mensual de Hoteles empalmadas
A31: 10.1 Coeficientes de variación estimado porcentual Total nacional
A32: 10.2 Coeficientes de variación estimado porcentual Total regional

Sheet 1.1 V.A Ing.real
L4: Inicio
A7: ENCUESTA MENSUAL DE ALOJAMIENTO - EMA
A10: 1.1 Variaciones anuales de los ingresos reales
A11: Total nacional y 12 regiones
A12: Enero 2020 - octubre 2021
A14: Año | B14: Meses | C14: Total nacional | D14: Bogotá D.C. | E14: Cartagena | F14: Central | G14: Caribe | H14: Eje Cafetero | I14: Antioquia | J14: San Andrés y Providencia | K14: Pacífico | L14: Santanderes | M14: Llanos Orinoquía | N14: Golfo de Morrosquillo y Sabana | O14: Amazonía
A15: 2020(p) | B15: Enero | C15: 8.1592411 | D15: 4.1596066 | E15: 10.449723 | F15: 3.8583185 | G15: 11.948117 | H15: 17.289324 | I15: 10.455827 | J15: 1.9115722 | K15: 8.3367292 | L15: 12.281732 | M15: -0.29511843 | N15: 7.3944022 | O15: 13.948905
B16: Febrero | C16: 10.410571 | D16: 6.9185238 | E16: 9.6222836 | F16: 6.2568595 | G16: 29.292181 | H16: 6.4126241 | I16: 14.181219 | J16: 10.42343 | K16: 6.8803348 | L16: 4.7515078 | M16: -3.970139 | N16: 3.6955686 | O16: 5.5799746
B17: Marzo | C17: -45.127161 | D17: -42.846109 | E17: -49.792227 | F17: -52.682472 | G17: -51.348371 | H17: -51.788265 | I17: -42.779947 | J17: -32.13802 | K17: -42.315828 | L17: -39.810125 | M17: -42.08341 | N17: -46.103127 | O17: -50.171494
B18: Abril | C18: -94.943711 | D18: -88.299 | E18: -98.939577 | F18: -97.432643 | G18: -96.449356 | H18: -97.655857 | I18: -94.581327 | J18: -100 | K18: -95.280684 | L18: -92.16249 | M18: -94.867819 | N18: -98.508163 | O18: -95.547848
B19: Mayo | C19: -94.641564 | D19: -91.058971 | E19: -98.544638 | F19: -93.165972 | G19: -95.614943 | H19: -96.061815 | I19: -93.909362 | J19: -100 | K19: -93.615444 | L19: -91.702503 | M19: -92.196968 | N19: -98.106636 | O19: -95.161696
B20: Junio | C20: -92.89611 | D20: -86.685411 | E20: -98.21943 | F20: -96.383613 | G20: -94.02829 | H20: -97.039872 | I20: -90.951472 | J20: -100 | K20: -91.488097 | L20: -87.701194 | M20: -81.405607 | N20: -93.594782 | O20: -92.52266
B21: Julio | C21: -91.833349 | D21: -88.639864 | E21: -98.40864 | F21: -93.65954 | G21: -92.240312 | H21: -92.459258 | I21: -86.544856 | J21: -100 | K21: -87.687599 | L21: -82.807935 | M21: -72.817543 | N21: -88.419472 | O21: -90.873262
B22: Agosto | C22: -91.461446 | D22: -88.176529 | E22: -98.648708 | F22: -90.580768 | G22: -92.751917 | H22: -86.078164 | I22: -88.521942 | J22: -99.992702 | K22: -86.526481 | L22: -81.319905 | M22: -71.795315 | N22: -87.19396 | O22: -89.127086
B23: Septiembre | C23: -83.147047 | D23: -85.286682 | E23: -93.01623 | F23: -74.902816 | G23: -80.462349 | H23: -60.737709 | I23: -76.304342 | J23: -99.997766 | K23: -73.306891 | L23: -65.551384 | M23: -49.393599 | N23: -70.188957 | O23: -86.353891
B24: Octubre | C24: -64.547525 | D24: -78.027666 | E24: -66.694745 | F24: -43.869316 | G24: -47.129279 | H24: -31.532234 | I24: -59.320128 | J24: -87.167169 | K24: -59.246891 | L24: -48.223915 | M24: -13.721049 | N24: -52.091067 | O24: -85.224085
B25: Noviembre | C25: -58.454006 | D25: -69.228043 | E25: -65.449106 | F25: -41.413225 | G25: -44.215725 | H25: -30.678386 | I25: -54.053443 | J25: -76.075322 | K25: -47.456662 | L25: -38.532696 | M25: -17.654247 | N25: -33.681107 | O25: -81.621371
B26: Diciembre | C26: -49.144591 | D26: -61.315812 | E26: -57.672846 | F26: -32.298848 | G26: -33.655355 | H26: -23.864402 | I26: -43.962677 | J26: -59.806264 | K26: -44.729681 | L26: -35.626734 | M26: -20.163447 | N26: -23.991387 | O26: -78.971258
A27: 2021(p) | B27: Enero | C27: -45.562467 | D27: -67.192311 | E27: -50.594362 | F27: -33.530523 | G27: -20.084274 | H27: -31.432758 | I27: -46.622661 | J27: -49.322744 | K27: -49.046072 | L27: -26.294864 | M27: -18.309695 | N27: -19.668786 | O27: -70.803195
B28: Febrero | C28: -52.112316 | D28: -70.560503 | E28: -60.899067 | F28: -26.284304 | G28: -35.659754 | H28: -27.962397 | I28: -46.742157 | J28: -44.428985 | K28: -48.105913 | L28: -28.488511 | M28: -18.900196 | N28: -9.3172201 | O28: -77.803872
B29: Marzo | C29: 14.933773 | D29: -35.005463 | E29: 18.250282 | F29: 114.87955 | G29: 58.712732 | H29: 84.623512 | I29: 20.48592 | J29: 4.6697146 | K29: 24.692943 | L29: 45.914013 | M29: 64.644262 | N29: 72.004846 | O29: -49.749893
B30: Abril | C30: 992.34888 | D30: 184.80118 | E30: 5547.478 | F30: 2615.5922 | G30: 1436.4889 | H30: 3110.504 | I30: 865.48385 | J30: - | K30: 1309.8817 | L30: 901.29244 | M30: 1352.389 | N30: 4745.6485 | O30: 429.81695
B31: Mayo | C31: 811.14944 | D31: 228.11791 | E31: 3453.273 | F31: 853.13033 | G31: 1487.8792 | H31: 1024.6774 | I31: 745.3727 | J31: - | K31: 502.2012 | L31: 729.2765 | M31: 789.77876 | N31: 3632.3264 | O31: 314.70028
B32: Junio | C32: 870.12948 | D32: 206.18226 | E32: 4454.3928 | F32: 2072.5658 | G32: 1520.5756 | H32: 2374.1193 | I32: 619.71093 | J32: - | K32: 539.20596 | L32: 507.54548 | M32: 537.00968 | N32: 1314.7726 | O32: 252.20614
B33: Julio | C33: 884.55668 | D33: 288.91098 | E33: 5657.0927 | F33: 1489.2477 | G33: 1323.197 | H33: 1221.8385 | I33: 503.16434 | J33: - | K33: 481.54109 | L33: 430.13177 | M33: 381.06024 | N33: 902.06613 | O33: 318.95164
B34: Agosto | C34: 822.45701 | D34: 315.39324 | E34: 6249.3935 | F34: 915.60544 | G34: 1273.7928 | H34: 536.16145 | I34: 584.78508 | J34: * | K34: 480.09734 | L34: 395.01585 | M34: 367.70884 | N34: 753.43495 | O34: 432.99141
B35: Septiembre | C35: 391.98746 | D35: 257.64388 | E35: 1250.6586 | F35: 314.59905 | G35: 442.67719 | H35: 166.06654 | I35: 264.30791 | J35: * | K35: 219.04085 | L35: 180.51068 | M35: 145.55187 | N35: 256.17904 | O35: 315.37694
B36: Octubre | C36: 175.05895 | D36: 171.79898 | E36: 242.94461 | F36: 116.39146 | G36: 172.24661 | H36: 71.360062 | I36: 147.90882 | J36: 666.31363 | K36: 123.87744 | L36: 116.01579 | M36: 55.135559 | N36: 138.76209 | O36: 342.52349
B38: Fuente: DANE, EMA
B39: (p): Cifra provisional
B40: Nota metodológica: Regiones: Bogotá DC, Cartagena, Región Central (Boyacá, Cundinamarca, Huila y Tolima), Región Costa Caribe (Atlántico, Cesar, La Guajira y Magdalena), Región Eje Cafetero (Caldas, Quindío y Risaralda), Antioquia, San Andrés y Providencia, Región Pacífico (Valle del Cauca, Cauca, Nariño y Chocó), Región Santanderes (Santander y Norte de Santander), Llanos Orinoquía (Meta, Casanare, Arauca y Vichada), Región Golfo Morrosquillo y Sabana (Bolívar, Córdoba y Sucre), Región Amazonía (Amazonas, Caquetá, Guainía, Putumayo, Guaviare y Vaupés). Nota: San Andrés y Providencia no presenta variación anual en ingresos reales, dado que para los meses de abril hasta agosto 2020 no se presentó oferta de alojamiento en los establecimientos de la muestra.
B43: Variación anual = ((Valor mes año actual-valor mes año anterior)/(valor mes año anterior))*100
B44: * Variación anual superior a 10.000%
B45: Actualizado el 15 de diciembre de 2021

Sheet 1.2 V.A.C Ing.real
L4: Inicio
A7: ENCUESTA MENSUAL DE ALOJAMIENTO - EMA
A10: 1.2 Variaciones año corrido de los ingresos reales
A11: Total nacional y 12 regiones
A12: ='1.1 V.A Ing.real'!A12 -> Enero 2020 - octubre 2021
A14: Año | B14: Meses | C14: Total nacional | D14: Bogotá D.C. | E14: Cartagena | F14: Central | G14: Caribe | H14: Eje Cafetero | I14: Antioquia | J14: San Andrés y Providencia | K14: Pacífico | L14: Santanderes | M14: Llanos Orinoquía | N14: Golfo de Morrosquillo y Sabana | O14: Amazonía*
A15: 2020(p) | B15: Enero | C15: 8.1592411 | D15: 4.1596066 | E15: 10.449723 | F15: 3.8583185 | G15: 11.948117 | H15: 17.289324 | I15: 10.455827 | J15: 1.9115722 | K15: 8.3367292 | L15: 12.281732 | M15: -0.29511843 | N15: 7.3944022 | O15: 13.948905
B16: Febrero | C16: 9.2324136 | D16: 5.735775 | E16: 10.073638 | F16: 4.7916769 | G16: 19.251741 | H16: 12.996356 | I16: 12.266913 | J16: 5.6652043 | K16: 7.5800799 | L16: 8.481047 | M16: -1.9464536 | N16: 5.777685 | O16: 10.365929
B17: Marzo | C17: -9.4580825 | D17: -12.742834 | E17: -9.5681501 | F17: -12.42476 | G17: -5.6597482 | H17: -7.0815816 | I17: -6.7095726 | J17: -6.4758854 | K17: -10.131891 | L17: -8.469745 | M17: -15.37055 | N17: -11.682999 | O17: -7.5097074
B18: Abril | C18: -30.051357 | D18: -32.003726 | E18: -29.284367 | F18: -33.588254 | G18: -27.311858 | H18: -29.066747 | I18: -27.680363 | J18: -28.485584 | K18: -31.745894 | L18: -30.70031 | M18: -36.3453 | N18: -32.996964 | O18: -28.50056
B19: Mayo | C19: -42.93495 | D19: -46.126239 | E19: -41.130061 | F19: -43.984155 | G19: -39.207292 | H19: -41.269472 | I19: -41.461162 | J19: -41.996096 | K19: -45.684165 | L19: -43.291524 | M19: -46.401006 | N19: -45.526591 | O19: -41.858951
B20: Junio | C20: -51.304689 | D20: -53.032165 | E20: -49.092626 | F20: -54.614665 | G20: -48.57465 | H20: -51.390429 | I20: -50.177061 | J20: -52.001782 | K20: -53.973655 | L20: -51.644181 | M20: -51.033197 | N20: -54.065993 | O20: -51.25688
B21: Julio | C21: -57.457835 | D21: -58.537971 | E21: -55.946016 | F21: -60.84225 | G21: -55.240694 | H21: -57.633302 | I21: -56.173644 | J21: -59.200499 | K21: -59.333057 | L21: -56.436022 | M21: -53.687243 | N21: -59.168431 | O21: -59.041386
B22: Agosto | C22: -62.175434 | D22: -62.679499 | E22: -61.619826 | F22: -64.827545 | G22: -60.594532 | H22: -61.599433 | I22: -61.049059 | J22: -64.535503 | K22: -63.382726 | L22: -60.016768 | M22: -55.636926 | N22: -62.908001 | O22: -63.58458
B23: Septiembre | C23: -64.611452 | D23: -65.613427 | E23: -64.844928 | F23: -65.895239 | G23: -62.824353 | H23: -61.512174 | I23: -62.877572 | J23: -68.558087 | K23: -64.63115 | L23: -60.713198 | M23: -54.965866 | N23: -63.708664 | O23: -66.466575
B24: Octubre | C24: -64.604732 | D24: -67.038865 | E24: -65.018612 | F24: -63.457933 | G24: -61.295247 | H24: -58.376594 | I24: -62.514907 | J24: -70.475694 | K24: -64.028856 | L24: -59.29502 | M24: -50.667074 | N24: -62.409842 | O24: -68.702294
B25: Noviembre | C25: -63.985797 | D25: -67.271424 | E25: -65.060954 | F25: -61.137268 | G25: -59.593249 | H25: -55.75136 | I25: -61.686443 | J25: -70.996699 | K25: -62.348062 | L25: -57.146215 | M25: -47.387012 | N25: -59.683317 | O25: -70.0368
B26: Diciembre | C26: -62.577211 | D26: -66.78587 | E26: -64.287266 | F26: -58.092365 | G26: -56.902904 | H26: -52.593411 | I26: -60.074667 | J26: -69.947646 | K26: -60.697664 | L26: -55.033555 | M26: -44.449733 | N26: -56.353226 | O26: -70.925852
A27: 2021(p) | B27: Enero | C27: -45.562467 | D27: -67.192311 | E27: -50.594362 | F27: -33.530523 | G27: -20.084274 | H27: -31.432758 | I27: -46.622661 | J27: -49.322744 | K27: -49.046072 | L27: -26.294864 | M27: -18.309695 | N27: -19.668786 | O27: -70.803195
B28: Febrero | C28: -48.71835 | D28: -69.138082 | E28: -55.258817 | F28: -30.671334 | G28: -27.19537 | H28: -30.142835 | I28: -46.681745 | J28: -47.067471 | K28: -48.560802 | L28: -27.363986 | M28: -18.569555 | N28: -15.233297 | O28: -73.670412
B29: Marzo | C29: -35.454628 | D29: -60.634357 | E29: -41.868452 | F29: -7.1139926 | G29: -11.562857 | H29: -11.687893 | I29: -32.479576 | J29: -35.010602 | K29: -31.869783 | L29: -10.449663 | M29: 0.47704766 | N29: 2.6843155 | O29: -69.865103
B30: Abril | C30: -17.557018 | D30: -49.867678 | E30: -23.377906 | F30: 18.12774 | G30: 5.3062374 | H30: 13.35697 | I30: -16.422708 | J30: -11.657691 | K30: -8.3204266 | L30: 16.939674 | M30: 29.235435 | N30: 28.607915 | O30: -62.446531
B31: Mayo | C31: -2.0353308 | D31: -38.834871 | E31: -8.6779894 | F31: 35.903654 | G31: 23.930529 | H31: 25.708906 | I31: 0.06966754 | J31: 11.870038 | K31: 5.1987514 | L31: 38.452959 | M31: 49.170016 | N31: 52.712129 | O31: -56.157234
B32: Junio | C32: 19.279752 | D32: -27.008363 | E32: 13.094587 | F32: 68.827128 | G32: 53.627388 | H32: 51.661488 | I32: 19.88863 | J32: 42.7473 | K32: 23.071542 | L32: 60.892802 | M32: 73.684274 | N32: 83.976479 | O32: -47.382544
B33: Julio | C33: 44.497978 | D33: -13.624355 | E33: 41.427271 | F33: 105.51104 | G33: 87.22787 | H33: 83.321659 | I33: 44.353043 | J33: 77.822854 | K33: 45.137282 | L33: 83.298614 | M33: 95.663979 | N33: 118.43846 | O33: -31.342557
B34: Agosto | C34: 68.862789 | D34: 0.94097072 | E34: 70.468246 | F34: 134.58402 | G34: 118.37817 | H34: 106.21276 | I34: 68.355278 | J34: 112.46732 | K34: 68.971452 | L34: 104.25505 | M34: 114.28622 | N34: 147.69168 | O34: -10.406625
B35: Septiembre | C35: 86.737214 | D35: 15.195585 | E35: 94.551636 | F35: 148.62214 | G35: 137.5066 | H35: 112.3956 | I35: 83.347336 | J35: 145.63033 | K35: 83.218946 | L35: 112.66874 | M35: 118.06261 | N35: 157.49142 | O35: 6.3738179
B36: Octubre | C36: 96.036936 | D36: 27.182392 | E36: 107.81701 | F36: 143.14376 | G36: 142.12993 | H36: 105.33574 | I36: 90.490028 | J36: 168.95154 | K36: 88.371711 | L36: 113.15217 | M36: 106.59211 | N36: 154.82273 | O36: 25.289268
B38: Fuente: DANE, EMA
B39: (p): Cifra provisional
B40: Nota metodológica: Regiones: Bogotá DC, Cartagena, Región Central (Boyacá, Cundinamarca, Huila y Tolima), Región Costa Caribe (Atlántico, Cesar, La Guajira y Magdalena), Región Eje Cafetero (Caldas, Quindío y Risaralda), Antioquia, San Andrés y Providencia, Región Pacífico (Valle del Cauca, Cauca, Nariño y Chocó), Región Santanderes (Santander y Norte de Santander), Llanos Orinoquía (Meta, Casanare, Arauca y Vichada), Región Golfo Morrosquillo y Sabana (Bolívar, Córdoba y Sucre), Región Amazonía (Amazonas, Caquetá, Guainía, Putumayo, Guaviare y Vaupés).
B44: Variación año corrido=((valor de los meses transcurridos del año de referencia-valor de los mismos meses transcurridos del año anterior)/(valor de los meses transcurridos del año anterior))*100
B45: * Ajuste de información histórica de algunas fuentes.
B46: ='1.1 V.A Ing.real'!B45 -> Actualizado el 15 de diciembre de 2021

Sheet 1.3 V.12Meses Ing.real
L4: Inicio
A7: ENCUESTA MENSUAL DE ALOJAMIENTO - EMA
A10: 1.3 Variaciones 12 meses de los ingresos reales
A11: Total nacional y 12 regiones
A12: Diciembre 2020 - octubre 2021
A14: Año | B14: Meses | C14: Total nacional | D14: Bogotá D.C. | E14: Cartagena | F14: Central | G14: Caribe | H14: Eje Cafetero | I14: Antioquia | J14: San Andrés y Providencia | K14: Pacífico | L14: Santanderes | M14: Llanos Orinoquía | N14: Golfo de Morrosquillo y Sabana | O14: Amazonía*
A15: 2020(p) | B15: Diciembre | C15: -62.577211 | D15: -66.78587 | E15: -64.287266 | F15: -58.092365 | G15: -56.902904 | H15: -52.593411 | I15: -60.074667 | J15: -69.947646 | K15: -60.697664 | L15: -55.033555 | M15: -44.449733 | N15: -56.353226 | O15: -70.925852
A16: 2021(p) | B16: Enero | C16: -66.824537 | D16: -70.87699 | E16: -70.178194 | F16: -61.64777 | G16: -59.410804 | H16: -57.08504 | I16: -64.321296 | J16: -74.720603 | K16: -64.42322 | L16: -57.432607 | M16: -46.19823 | N16: -58.520114 | O16: -78.019712
B17: Febrero | C17: -71.298998 | D17: -76.762931 | E17: -75.86632 | F17: -63.525438 | G17: -63.166878 | H17: -59.189017 | I17: -68.495297 | J17: -78.519844 | K17: -68.250984 | L17: -59.648092 | M17: -47.465106 | N17: -59.291642 | O17: -83.226839
B18: Marzo | C18: -69.529254 | D18: -77.613309 | E18: -73.922507 | F18: -58.333407 | G18: -59.006272 | H18: -54.447043 | I18: -66.480584 | J18: -77.705028 | K18: -66.098855 | L18: -56.292683 | M18: -41.992725 | N18: -54.509867 | O18: -84.259404
B19: Abril | C19: -62.935289 | D19: -74.236266 | E19: -66.652371 | F19: -49.226146 | G19: -51.392896 | H19: -44.371213 | I19: -60.344649 | J19: -69.86778 | K19: -58.549631 | L19: -46.826351 | M19: -28.475513 | N19: -44.430958 | O19: -81.818468
B20: Mayo | C20: -55.561805 | D20: -69.379689 | E20: -59.400159 | F20: -41.104345 | G20: -42.450369 | H20: -36.381135 | I20: -52.618545 | J20: -60.580791 | K20: -51.424887 | L20: -36.936957 | M20: -15.894325 | N20: -33.052258 | O20: -79.188629
B21: Junio | C21: -44.855685 | D21: -63.788132 | E21: -48.67386 | F21: -24.53838 | G21: -27.381881 | H21: -21.160469 | I21: -42.182109 | J21: -46.638625 | K21: -41.633387 | L21: -23.809778 | M21: -0.80644949 | N21: -16.201184 | O21: -75.361295
B22: Julio | C22: -29.674014 | D22: -55.776455 | E22: -32.367874 | F22: -2.710376 | G22: -6.688596 | H22: -0.15327417 | I22: -26.710796 | J22: -27.537081 | K22: -27.74997 | L22: -7.601879 | M22: 16.929301 | N22: 6.139672 | O22: -67.610876
B23: Agosto | C23: -9.6336299 | D23: -44.610203 | E23: -10.235625 | F23: 22.59684 | G23: 20.4534 | H23: 24.51645 | I23: -5.3714242 | J23: -2.9346142 | K23: -7.7609142 | L23: 13.914747 | M23: 37.12705 | N23: 33.786219 | O23: -55.835278
B24: Septiembre | C24: 12.936512 | D24: -29.263675 | E24: 14.180785 | F24: 46.85327 | G24: 48.093329 | H24: 43.423928 | I24: 16.795457 | J24: 29.021813 | K24: 13.782752 | L24: 35.763591 | M24: 55.224236 | N24: 59.267024 | O24: -41.975986
B25: Octubre | C25: 37.295529 | D25: -9.7818161 | E25: 39.234447 | F25: 70.199315 | G25: 73.118356 | H25: 58.742406 | I25: 39.002213 | J25: 68.875138 | K25: 36.226693 | L25: 57.901578 | M25: 64.951308 | N25: 87.372706 | O25: -20.34702
B27: Fuente: DANE, EMA
B28: (p): Cifra provisional
B29: Nota metodológica: Regiones: Bogotá DC, Cartagena, Región Central (Boyacá, Cundinamarca, Huila y Tolima), Región Costa Caribe (Atlántico, Cesar, La Guajira y Magdalena), Región Eje Cafetero (Caldas, Quindío y Risaralda), Antioquia, San Andrés y Providencia, Región Pacífico (Valle del Cauca, Cauca, Nariño y Chocó), Región Santanderes (Santander y Norte de Santander), Llanos Orinoquía (Meta, Casanare, Arauca y Vichada), Región Golfo Morrosquillo y Sabana (Bolívar, Córdoba y Sucre), Región Amazonía (Amazonas, Caquetá, Guainía, Putumayo, Guaviare y Vaupés).
B33: * Ajuste de información histórica de algunas fuentes.
B34: ='1.1 V.A Ing.real'!B45 -> Actualizado el 15 de diciembre de 2021

Sheet 2.1 V.A Per.categ
L4: Inicio
A7: ENCUESTA MENSUAL DE ALOJAMIENTO - EMA
A10: 2.1 Variaciones anuales del personal total y por categoría
A11: Total nacional y 12 regiones
A12: ='1.1 V.A Ing.real'!A12 -> Enero 2020 - octubre 2021
A14: Año | B14: Meses | C14: Total nacional | F14: Bogotá D.C. | I14: Cartagena | L14: Central | O14: Caribe | R14: Eje Cafetero | U14: Antioquia | X14: San Andrés y Providencia | AA14: Pacífico | AD14: Santanderes | AG14: Llanos Orinoquía | AJ14: Golfo de Morrosquillo y Sabana | AM14: Amazonía
C15: Total del personal | D15: Personal permanente | E15: Resto de personal | F15: Total del personal | G15: Personal permanente | H15: Resto de personal | I15: Total del personal | J15: Personal permanente | K15: Resto de personal | L15: Total del personal | M15: Personal permanente | N15: Resto de personal | O15: Total del personal | P15: Personal permanente | Q15: Resto de personal | R15: Total del personal | S15: Personal permanente | T15: Resto de personal | U15: Total del personal | V15: Personal permanente | W15: Resto de personal | X15: Total del personal | Y15: Personal permanente | Z15: Resto de personal | AA15: Total del personal | AB15: Personal permanente | AC15: Resto de personal | AD15: Total del personal | AE15: Personal permanente | AF15: Resto de personal | AG15: Total del personal | AH15: Personal permanente | AI15: Resto de personal | AJ15: Total del personal | AK15: Personal permanente | AL15: Resto de personal | AM15: Total del personal | AN15: Personal permanente | AO15: Resto de personal
A16: 2020(p) | B16: Enero | C16: 2.1770988 | D16: 1.0500609 | E16: 3.6622839 | F16: 1.3476145 | G16: 2.2650545 | H16: -0.44416244 | I16: 3.9930471 | J16: 2.2090602 | K16: 6.4614258 | L16: 2.0052343 | M16: 3.9928562 | N16: 0.066651357 | O16: 4.7674563 | P16: -0.94763238 | Q16: 12.224642 | R16: 4.1703674 | S16: 8.2823025 | T16: 2.362939 | U16: 4.0186164 | V16: 0.90153469 | W16: 8.8948853 | X16: -6.8581622 | Y16: -0.92100287 | Z16: -15.238006 | AA16: 1.9062285 | AB16: -0.087296466 | AC16: 5.0870553 | AD16: 2.4784314 | AE16: -1.0030316 | AF16: 5.5127871 | AG16: -8.2130078 | AH16: -14.400871 | AI16: -2.4307818 | AJ16: 6.0587337 | AK16: -3.5000699 | AL16: 16.424242 | AM16: 0.96618357 | AN16: 11.260054 | AO16: -11.146162
B17: Febrero | C17: 2.4349063 | D17: 0.29154968 | E17: 5.4032132 | F17: 2.044 | G17: 1.4240517 | H17: 3.2363325 | I17: 4.1387457 | J17: 2.3209316 | K17: 6.8077568 | L17: 2.3862805 | M17: 4.2823152 | N17: 0.42806705 | O17: 2.7718323 | P17: -3.333541 | Q17: 11.226286 | R17: 6.6262601 | S17: 4.8020127 | T17: 7.4917485 | U17: 3.968371 | V17: -2.8959359 | W17: 16.511697 | X17: -4.2476602 | Y17: -0.15185351 | Z17: -10.315622 | AA17: 2.002956 | AB17: 1.3415793 | AC17: 3.0369158 | AD17: 3.8464974 | AE17: 0.65145339 | AF17: 6.6680124 | AG17: -8.1596492 | AH17: -12.222374 | AI17: -4.2927546 | AJ17: 3.2247377 | AK17: -3.5271754 | AL17: 10.62418 | AM17: 2.6666667 | AN17: 13.388735 | AO17: -9.6602972
B18: Marzo | C18: -6.6450653 | D18: -2.9136001 | E18: -11.681285 | F18: -6.257584 | G18: -1.7847118 | H18: -14.59523 | I18: -6.159635 | J18: 1.9250636 | K18: -17.562463 | L18: -5.7614015 | M18: -0.14157342 | N18: -11.452291 | O18: -6.7471244 | P18: -6.3018544 | Q18: -7.3527447 | R18: -6.7589385 | S18: 1.4760228 | T18: -10.728591 | U18: -6.2121916 | V18: -5.9789435 | W18: -6.6101476 | X18: -11.966506 | Y18: -6.7209412 | Z18: -19.388013 | AA18: -6.2106095 | AB18: -1.6038045 | AC18: -13.235855 | AD18: -4.1777825 | AE18: -8.7323837 | AF18: -0.14750251 | AG18: -12.079414 | AH18: -16.314396 | AI18: -8.0627396 | AJ18: -3.0726973 | AK18: -4.3101016 | AL18: -1.7366136 | AM18: -5.0756467 | AN18: 3.240324 | AO18: -14.925373
B19: Abril | C19: -24.469863 | D19: -10.879952 | E19: -42.814927 | F19: -24.642457 | G19: -12.962374 | H19: -47.007496 | I19: -24.957286 | J19: -6.6133298 | K19: -51.530412 | L19: -21.722348 | M19: -6.905674 | N19: -36.626759 | O19: -24.666247 | P19: -8.3551536 | Q19: -46.104866 | R19: -29.465395 | S19: -20.548965 | T19: -33.673923 | U19: -26.755048 | V19: -13.651547 | W19: -48.660175 | X19: -20.078478 | Y19: -11.368726 | Z19: -32.511059 | AA19: -21.164365 | AB19: -8.3531042 | AC19: -41.36146 | AD19: -24.90225 | AE19: -14.538003 | AF19: -33.961895 | AG19: -32.84946 | AH19: -27.004082 | AI19: -38.059208 | AJ19: -14.743246 | AK19: -10.142776 | AL19: -19.460752 | AM19: -22.516226 | AN19: -5.1959891 | AO19: -43.487859
B20: Mayo | C20: -30.848459 | D20: -18.667199 | E20: -47.649193 | F20: -33.495014 | G20: -22.085224 | H20: -54.881618 | I20: -31.804577 | J20: -15.443074 | K20: -55.658881 | L20: -24.653736 | M20: -11.892664 | N20: -37.918661 | O20: -30.05295 | P20: -17.204483 | Q20: -47.991938 | R20: -36.76747 | S20: -26.031963 | T20: -41.821507 | U20: -35.371422 | V20: -25.69167 | W20: -52.590741 | X20: -21.289199 | Y20: -11.805865 | Z20: -35.597095 | AA20: -25.795697 | AB20: -10.615484 | AC20: -49.012284 | AD20: -33.326307 | AE20: -22.302944 | AF20: -42.971478 | AG20: -31.832637 | AH20: -29.670382 | AI20: -34.017176 | AJ20: -23.158532 | AK20: -23.194131 | AL20: -23.12226 | AM20: -31.065089 | AN20: -13.26624 | AO20: -51.871658
B21: Junio | C21: -37.80748 | D21: -25.216767 | E21: -55.047502 | F21: -41.753682 | G21: -31.430353 | H21: -61.228103 | I21: -38.637938 | J21: -23.925704 | K21: -60.916844 | L21: -32.248954 | M21: -15.21035 | N21: -48.80627 | O21: -38.590749 | P21: -25.743467 | Q21: -56.776192 | R21: -45.810029 | S21: -34.783576 | T21: -50.770371 | U21: -41.667557 | V21: -31.376664 | W21: -58.76255 | X21: -26.612369 | Y21: -12.697849 | Z21: -48.326751 | AA21: -30.136247 | AB21: -15.901234 | AC21: -52.176202 | AD21: -41.119277 | AE21: -23.557343 | AF21: -55.832157 | AG21: -30.687704 | AH21: -26.421975 | AI21: -35.02262 | AJ21: -26.323183 | AK21: -24.201301 | AL21: -28.418848 | AM21: -32.070831 | AN21: -13.394495 | AO21: -53.658537
B22: Julio | C22: -42.72799 | D22: -29.335902 | E22: -60.388391 | F22: -48.665213 | G22: -35.029565 | H22: -71.190214 | I22: -41.239708 | J22: -26.221034 | K22: -63.076385 | L22: -33.639287 | M22: -15.458943 | N22: -50.983817 | O22: -42.722827 | P22: -30.015612 | Q22: -60.202171 | R22: -48.863135 | S22: -40.037034 | T22: -53.095656 | U22: -47.477632 | V22: -37.315057 | W22: -63.770329 | X22: -37.363299 | Y22: -17.332057 | Z22: -69.321492 | AA22: -36.308437 | AB22: -22.495676 | AC22: -57.373058 | AD22: -43.650905 | AE22: -28.58884 | AF22: -56.402154 | AG22: -33.633769 | AH22: -34.217172 | AI22: -33.060272 | AJ22: -34.403234 | AK22: -33.249016 | AL22: -35.558995 | AM22: -36.194213 | AN22: -25.760286 | AO22: -48.859935
B23: Agosto | C23: -45.036908 | D23: -32.40973 | E23: -61.754792 | F23: -50.089873 | G23: -39.197064 | H23: -68.779625 | I23: -42.91999 | J23: -28.499882 | K23: -64.286882 | L23: -34.97265 | M23: -17.038947 | N23: -52.223011 | O23: -47.041655 | P23: -34.854973 | Q23: -63.540013 | R23: -50.802085 | S23: -41.366143 | T23: -55.240157 | U23: -49.17185 | V23: -39.645508 | W23: -64.402856 | X23: -37.58111 | Y23: -16.515451 | Z23: -71.011084 | AA23: -42.626828 | AB23: -30.237008 | AC23: -61.453206 | AD23: -46.231511 | AE23: -30.627545 | AF23: -59.180773 | AG23: -35.925346 | AH23: -30.710792 | AI23: -40.843066 | AJ23: -36.861327 | AK23: -35.637848 | AL23: -38.07889 | AM23: -41.863834 | AN23: -25.670841 | AO23: -60.860441
B24: Septiembre | C24: -44.651599 | D24: -34.015973 | E24: -58.80056 | F24: -52.580842 | G24: -41.837274 | H24: -70.786491 | I24: -42.870429 | J24: -28.855149 | K24: -63.915933 | L24: -34.609272 | M24: -20.191546 | N24: -48.939119 | O24: -44.771115 | P24: -37.414917 | Q24: -54.676603 | R24: -42.859961 | S24: -40.721257 | T24: -43.930263 | U24: -47.307908 | V24: -39.51743 | W24: -59.513607 | X24: -37.544089 | Y24: -16.214632 | Z24: -71.748798 | AA24: -44.463303 | AB24: -36.014013 | AC24: -57.261507 | AD24: -44.64181 | AE24: -29.215746 | AF24: -57.461791 | AG24: -34.669051 | AH24: -33.626889 | AI24: -35.64395 | AJ24: -38.676746 | AK24: -34.937179 | AL24: -42.339697 | AM24: -40.970221 | AN24: -22.232223 | AO24: -62.409887
B25: Octubre | C25: -41.55028 | D25: -34.880453 | E25: -50.265563 | F25: -53.375589 | G25: -44.484784 | H25: -68.681104 | I25: -40.592699 | J25: -29.59231 | K25: -56.515146 | L25: -28.976223 | M25: -18.694426 | N25: -38.856066 | O25: -38.089302 | P25: -36.231427 | Q25: -40.449874 | R25: -35.738279 | S25: -41.056162 | T25: -33.064449 | U25: -44.75881 | V25: -39.360374 | W25: -53.084694 | X25: -30.59494 | Y25: -16.640488 | Z25: -53.024128 | AA25: -43.2217 | AB25: -37.290357 | AC25: -52.262529 | AD25: -45.01442 | AE25: -34.685405 | AF25: -53.399499 | AG25: -26.073216 | AH25: -32.321619 | AI25: -20.424569 | AJ25: -35.36954 | AK25: -36.907449 | AL25: -33.876601 | AM25: -36.131211 | AN25: -29.133155 | AO25: -44.339623
B26: Noviembre | C26: -40.237918 | D26: -35.419401 | E26: -46.525069 | F26: -54.095795 | G26: -46.483855 | H26: -66.942863 | I26: -40.158499 | J26: -30.203131 | K26: -54.45278 | L26: -27.12587 | M26: -19.275313 | N26: -34.957789 | O26: -35.990754 | P26: -39.536936 | Q26: -31.36182 | R26: -32.411778 | S26: -35.797462 | T26: -30.775681 | U26: -41.898783 | V26: -37.146354 | W26: -49.195324 | X26: -28.906131 | Y26: -15.735175 | Z26: -50.293164 | AA26: -40.853826 | AB26: -37.099118 | AC26: -46.61358 | AD26: -41.872989 | AE26: -32.554428 | AF26: -49.366044 | AG26: -26.628833 | AH26: -32.659933 | AI26: -21.429543 | AJ26: -33.254223 | AK26: -38.856368 | AL26: -27.895384 | AM26: -34.608121 | AN26: -33.611343 | AO26: -35.908596
B27: Diciembre | C27: -37.951461 | D27: -34.212301 | E27: -42.609097 | F27: -53.062108 | G27: -47.414005 | H27: -62.894731 | I27: -37.76886 | J27: -29.592864 | K27: -48.925625 | L27: -28.356787 | M27: -20.68836 | N27: -35.585257 | O27: -30.251776 | P27: -36.798341 | Q27: -22.49804 | R27: -31.703556 | S27: -36.16794 | T27: -29.620578 | U27: -38.657227 | V27: -33.003385 | W27: -46.362849 | X27: -25.50444 | Y27: -13.44255 | Z27: -45.507949 | AA27: -40.273011 | AB27: -35.872259 | AC27: -46.663713 | AD27: -39.17768 | AE27: -29.113113 | AF27: -47.155662 | AG27: -26.252568 | AH27: -25.943421 | AI27: -26.485915 | AJ27: -33.480237 | AK27: -39.350384 | AL27: -27.870177 | AM27: -28.943489 | AN27: -30.099502 | AO27: -27.261761
A28: 2021(p) | B28: Enero | C28: -37.469315 | D28: -35.218167 | E28: -40.361074 | F28: -53.149096 | G28: -49.467861 | H28: -60.534264 | I28: -37.228732 | J28: -29.685621 | K28: -47.248734 | L28: -28.851783 | M28: -23.614355 | N28: -34.160416 | O28: -28.373298 | P28: -33.705219 | Q28: -22.232675 | R28: -32.815785 | S28: -36.33334 | T28: -31.180211 | U28: -40.114058 | V28: -37.803486 | W28: -43.463321 | X28: -22.357826 | Y28: -11.201922 | Z28: -40.763104 | AA28: -41.392969 | AB28: -38.578863 | AC28: -45.662008 | AD28: -37.998537 | AE28: -31.635855 | AF28: -43.201632 | AG28: -27.355072 | AH28: -31.967422 | AI28: -23.573843 | AJ28: -29.118262 | AK28: -36.885543 | AL28: -22.136908 | AM28: -27.416268 | AN28: -24.899598 | AO28: -31.12426
B29: Febrero | C29: -37.979844 | D29: -35.258913 | E29: -41.565284 | F29: -54.870684 | G29: -49.396351 | H29: -65.214519 | I29: -40.471871 | J29: -32.272727 | K29: -52.004573 | L29: -25.572851 | M29: -21.369689 | N29: -30.080452 | O29: -28.745326 | P29: -32.759215 | Q29: -23.91466 | R29: -32.518205 | S29: -41.388164 | T29: -28.415279 | U29: -39.812668 | V29: -38.025126 | W29: -42.534994 | X29: -22.634364 | Y29: -11.404097 | Z29: -41.157592 | AA29: -39.512455 | AB29: -37.694412 | AC29: -42.307919 | AD29: -36.137013 | AE29: -29.87888 | AF29: -41.351795 | AG29: -25.214036 | AH29: -28.852323 | AI29: -22.038032 | AJ29: -20.309547 | AK29: -18.017952 | AL29: -22.499651 | AM29: -31.216931 | AN29: -35.423453 | AO29: -25.146886
B30: Marzo | C30: -30.481481 | D30: -32.728664 | E30: -27.147453 | F30: -50.936187 | G30: -47.386843 | H30: -58.544739 | I30: -31.632872 | J30: -32.042793 | K30: -30.918038 | L30: -19.318775 | M30: -19.027394 | N30: -19.651531 | O30: -19.236711 | P30: -30.258262 | Q30: -4.0760507 | R30: -21.067767 | S30: -39.734086 | T30: -10.839532 | U30: -32.891462 | V30: -35.185136 | W30: -28.951661 | X30: -12.9099 | Y30: -2.5631804 | Z30: -29.848871 | AA30: -32.873774 | AB30: -34.913709 | AC30: -29.345877 | AD30: -26.889025 | AE30: -22.825952 | AF30: -30.17525 | AG30: -14.909212 | AH30: -23.030808 | AI30: -7.8976374 | AJ30: -13.058263 | AK30: -16.373019 | AL30: -9.5729013 | AM30: -24.37018 | AN30: -29.642546 | AO30: -16.79198
B31: Abril | C31: -15.140756 | D31: -27.715271 | E31: 11.312957 | F31: -40.587979 | G31: -42.884886 | H31: -33.364278 | I31: -13.330706 | J31: -26.066021 | K31: 22.213998 | L31: -5.0529388 | M31: -15.810076 | N31: 10.842703 | O31: -3.2125006 | P31: -28.894473 | Q31: 54.186007 | R31: 4.2259968 | S31: -23.866329 | T31: 20.109347 | U31: -15.689174 | V31: -30.251566 | W31: 25.25492 | X31: -2.4165765 | Y31: 4.6372151 | Z31: -15.639652 | AA31: -20.608989 | AB31: -31.503956 | AC31: 6.2356483 | AD31: -6.7939373 | AE31: -18.314587 | AF31: 6.2385955 | AG31: 7.0223987 | AH31: -12.983794 | AI31: 28.035512 | AJ31: -4.3525708 | AK31: -8.6289625 | AL31: 0.5399568 | AM31: -8.7628866 | AN31: -24.326923 | AO31: 22.851562
B32: Mayo | C32: -9.7631038 | D32: -21.380808 | E32: 15.131127 | F32: -34.703733 | G32: -36.251752 | H32: -29.692937 | I32: -7.3930935 | J32: -19.74913 | K32: 26.959955 | L32: -2.1640544 | M32: -11.233923 | N32: 11.216361 | O32: 3.1219497 | P32: -21.271933 | Q32: 57.342471 | R32: 4.8428369 | S32: -13.438181 | T32: 15.784867 | U32: -6.0182262 | V32: -20.442709 | W32: 34.200316 | X32: -0.20601355 | Y32: 2.2967305 | Z32: -5.3769054 | AA32: -21.239351 | AB32: -30.121665 | AC32: 2.5752547 | AD32: 6.1729371 | AE32: -10.459765 | AF32: 26.000578 | AG32: 4.6931031 | AH32: -8.6483583 | AI32: 19.060014 | AJ32: 3.840808 | AK32: 5.9331374 | AL32: 1.71092 | AM32: -0.35765379 | AN32: -17.510549 | AO32: 35.777778
B33: Junio | C33: 3.4815158 | D33: -14.693538 | E33: 44.882777 | F33: -22.166135 | G33: -27.315127 | H33: -4.9877671 | I33: 7.7341733 | J33: -11.28943 | K33: 63.807501 | L33: 7.545624 | M33: -8.2853269 | N33: 33.025013 | O33: 20.588354 | P33: -15.0244 | Q33: 107.19074 | R33: 27.199633 | S33: 1.6720696 | T33: 42.412657 | U33: 8.0168026 | V33: -13.551827 | W33: 67.64044 | X33: 10.895415 | Y33: 4.9609683 | Z33: 26.541968 | AA33: -15.297539 | AB33: -26.693773 | AC33: 15.730887 | AD33: 22.169518 | AE33: -6.5771678 | AF33: 63.850959 | AG33: 8.8817715 | AH33: -12.82827 | AI33: 33.864158 | AJ33: 6.2446372 | AK33: 6.5087654 | AL33: 5.9684026 | AM33: 2.7516293 | AN33: -18.855932 | AO33: 49.427918
B34: Julio | C34: 17.201273 | D34: -7.6549162 | E34: 75.675326 | F34: -11.801465 | G34: -20.95605 | H34: 22.302385 | I34: 19.556941 | J34: -6.0829555 | K34: 94.047215 | L34: 13.263431 | M34: -5.2752918 | N34: 43.768249 | O34: 35.097281 | P34: -7.3652077 | Q34: 137.80947 | R34: 44.719944 | S34: 0.73474603 | T34: 71.685344 | U34: 25.970834 | V34: -4.3475465 | W34: 110.07047 | X34: 34.197933 | Y34: 12.311795 | Z34: 128.28856 | AA34: 0.027031898 | AB34: -16.990339 | AC34: 47.212401 | AD34: 34.499535 | AE34: 2.0641101 | AF34: 79.47637 | AG34: 25.954429 | AH34: 5.0978887 | AI34: 46.102499 | AJ34: 22.13945 | AK34: 18.778947 | AL34: 25.625068 | AM34: 15.603382 | AN34: -5.6626506 | AO34: 53.078556
B35: Agosto | C35: 25.741992 | D35: -0.95401504 | E35: 88.205804 | F35: -3.8197223 | G35: -13.207803 | H35: 27.551175 | I35: 26.901841 | J35: -1.6982303 | K35: 111.74541 | L35: 17.791593 | M35: -1.0943431 | N35: 49.335986 | O35: 49.066018 | P35: 0.30332557 | Q35: 167.01866 | R35: 51.785493 | S35: 8.0463097 | T35: 78.734313 | U35: 33.59084 | V35: 3.3338349 | W35: 115.6114 | X35: 39.017392 | Y35: 14.811427 | Z35: 149.64347 | AA35: 14.410611 | AB35: -4.5895229 | AC35: 66.661688 | AD35: 42.957566 | AE35: 6.0014263 | AF35: 95.079304 | AG35: 32.548973 | AH35: 7.8401922 | AI35: 59.842389 | AJ35: 28.309232 | AK35: 25.246117 | AL35: 31.47771 | AM35: 27.740864 | AN35: 8.543923 | AO35: 70.509383
B36: Septiembre | C36: 28.656329 | D36: 3.653997 | E36: 81.927165 | F36: 6.3174577 | G36: -6.6242369 | H36: 49.980081 | I36: 29.349019 | J36: -0.27158946 | K36: 117.04496 | L36: 22.406015 | M36: 4.810586 | N36: 49.740145 | O36: 47.373694 | P36: 8.3867864 | Q36: 119.86561 | R36: 39.038376 | S36: 10.602659 | T36: 54.083307 | U36: 27.945309 | V36: 4.0497345 | W36: 83.874325 | X36: 44.431598 | Y36: 15.580012 | Z36: 181.64832 | AA36: 20.605848 | AB36: 5.5909307 | AC36: 54.65587 | AD36: 43.102804 | AE36: 6.350314 | AF36: 93.927697 | AG36: 34.962797 | AH36: 21.747664 | AI36: 47.712468 | AJ36: 39.902074 | AK36: 27.166996 | AL36: 53.977686 | AM36: 25.874695 | AN36: 8.2175926 | AO36: 67.671233
B37: Octubre | C37: 25.755171 | D37: 8.199421 | E37: 55.791056 | F37: 13.368157 | G37: 0.33749954 | H37: 53.13113 | I37: 27.550156 | J37: 0.84291992 | K37: 90.141286 | L37: 15.698756 | M37: 5.4417827 | N37: 28.804664 | O37: 32.718459 | P37: 10.943969 | Q37: 62.344432 | R37: 24.723279 | S37: 12.200604 | T37: 30.267925 | U37: 27.64821 | V37: 8.4332448 | W37: 65.9522 | X37: 34.393622 | Y37: 17.617766 | Z37: 82.241843 | AA37: 22.922937 | AB37: 9.2924643 | AC37: 50.215295 | AD37: 50.563297 | AE37: 29.371975 | AF37: 74.674894 | AG37: 22.297459 | AH37: 40.118017 | AI37: 8.5959712 | AJ37: 39.123656 | AK37: 37.701252 | AL37: 40.441176 | AM37: 19.637462 | AN37: 18.537201 | AO37: 21.280603
B39: Fuente: DANE, EMA
B40: (p): Cifra provisional
B41: Nota metodológica: Regiones: Bogotá DC, Cartagena, Región Central (Boyacá, Cundinamarca, Huila y Tolima), Región Costa Caribe (Atlántico, Cesar, La Guajira y Magdalena), Región Eje Cafetero (Caldas, Quindío y Risaralda), Antioquia, San Andrés y Providencia, Región Pacífico (Valle del Cauca, Cauca, Nariño y Chocó), Región Santanderes (Santander y Norte de Santander), Llanos Orinoquía (Meta, Casanare, Arauca y Vichada), Región Golfo Morrosquillo y Sabana (Bolívar, Córdoba y Sucre), Región Amazonía (Amazonas, Caquetá, Guainía, Putumayo, Guaviare y Vaupés).
B45: Variación anual = ((Valor mes año actual-valor mes año anterior)/(valor mes año anterior))*100
B46: 1 El resto del personal lo conforman las siguientes categorías de contratación: los Propietarios, Socios y Familiares sin remuneración, el Temporal Directo, Temporal contratado a través de Agencias y los Aprendices.
B47: ='1.1 V.A Ing.real'!B45 -> Actualizado el 15 de diciembre de 2021

Sheet 2.2 V.A.C Per.categ
L4: Inicio
A7: ENCUESTA MENSUAL DE ALOJAMIENTO - EMA
A10: 2.2 Variaciones año corrido del personal total y por categoría
A11: Total nacional y 12 regiones
A12: ='1.1 V.A Ing.real'!A12 -> Enero 2020 - octubre 2021
A14: Año | B14: Meses | C14: Total nacional | F14: Bogotá D.C. | I14: Cartagena | L14: Central | O14: Caribe | R14: Eje Cafetero | U14: Antioquia | X14: San Andrés y Providencia | AA14: Pacífico | AD14: Santanderes | AG14: Llanos Orinoquía | AJ14: Golfo de Morrosquillo y Sabana | AM14: Amazonía
C15: Total del personal | D15: Personal permanente | E15: Resto de personal | F15: Total del personal | G15: Personal permanente | H15: Resto de personal | I15: Total del personal | J15: Personal permanente | K15: Resto de personal | L15: Total del personal | M15: Personal permanente | N15: Resto de personal | O15: Total del personal | P15: Personal permanente | Q15: Resto de personal | R15: Total del personal | S15: Personal permanente | T15: Resto de personal | U15: Total del personal | V15: Personal permanente | W15: Resto de personal | X15: Total del personal | Y15: Personal permanente | Z15: Resto de personal | AA15: Total del personal | AB15: Personal permanente | AC15: Resto de personal | AD15: Total del personal | AE15: Personal permanente | AF15: Resto de personal | AG15: Total del personal | AH15: Personal permanente | AI15: Resto de personal | AJ15: Total del personal | AK15: Personal permanente | AL15: Resto de personal | AM15: Total del personal | AN15: Personal permanente | AO15: Resto de personal
A16: 2020(p) | B16: Enero | C16: 2.1770988 | D16: 1.0500609 | E16: 3.6622839 | F16: 1.3476145 | G16: 2.2650545 | H16: -0.44416244 | I16: 3.9930471 | J16: 2.2090602 | K16: 6.4614258 | L16: 2.0052343 | M16: 3.9928562 | N16: 0.066651357 | O16: 4.7674563 | P16: -0.94763238 | Q16: 12.224642 | R16: 4.1703674 | S16: 8.2823025 | T16: 2.362939 | U16: 4.0186164 | V16: 0.90153469 | W16: 8.8948853 | X16: -6.8581622 | Y16: -0.92100287 | Z16: -15.238006 | AA16: 1.9062285 | AB16: -0.087296466 | AC16: 5.0870553 | AD16: 2.4784314 | AE16: -1.0030316 | AF16: 5.5127871 | AG16: -8.2130078 | AH16: -14.400871 | AI16: -2.4307818 | AJ16: 6.0587337 | AK16: -3.5000699 | AL16: 16.424242 | AM16: 0.96618357 | AN16: 11.260054 | AO16: -11.146162
B17: Febrero | C17: 2.3047158 | D17: 0.67058447 | E17: 4.5116406 | F17: 1.6994358 | G17: 1.841269 | H17: 1.4245749 | I17: 4.0651423 | J17: 2.2651014 | K17: 6.6297796 | L17: 2.1903939 | M17: 4.135578 | N17: 0.23968424 | O17: 3.7849315 | P17: -2.1374369 | Q17: 11.741616 | R17: 5.3659489 | S17: 6.542424 | T17: 4.8290903 | U17: 3.9938695 | V17: -1.0236225 | W17: 12.460762 | X17: -5.5683278 | Y17: -0.53716107 | Z17: -12.841125 | AA17: 1.9542673 | AB17: 0.6195157 | AC17: 4.0624669 | AD17: 3.1540036 | AE17: -0.18312944 | AF17: 6.0814839 | AG17: -8.1870083 | AH17: -13.334223 | AI17: -3.3338925 | AJ17: 4.65078 | AK17: -3.5135704 | AL17: 13.550705 | AM17: 1.8070818 | AN17: 12.306994 | AO17: -10.406762
B18: Marzo | C18: -0.68434926 | D18: -0.52625334 | E18: -0.89781555 | F18: -0.99624669 | G18: 0.62371707 | H18: -4.0943767 | I18: 0.64648533 | J18: 2.1517263 | K18: -1.4908828 | L18: -0.42131353 | M18: 2.7262045 | N18: -3.5878746 | O18: 0.27656131 | P18: -3.5295019 | Q18: 5.4109713 | R18: 1.4234439 | S18: 4.8532789 | T18: -0.17003289 | U18: 0.55915673 | V18: -2.6957876 | W18: 6.0721566 | X18: -7.7087297 | Y18: -2.5936835 | Z18: -15.049746 | AA18: -0.78543224 | AB18: -0.11970758 | AC18: -1.8245768 | AD18: 0.72298819 | AE18: -3.0265612 | AF18: 4.0217271 | AG18: -9.4445621 | AH18: -14.299034 | AI18: -4.8587137 | AJ18: 2.0784543 | AK18: -3.7780484 | AL18: 8.4423517 | AM18: -0.48828125 | AN18: 9.2665258 | AO18: -11.903921
B19: Abril | C19: -6.6648919 | D19: -3.1293472 | E19: -11.438407 | F19: -7.0495416 | G19: -2.8553274 | H19: -15.073348 | I19: -5.7232235 | J19: -0.042317112 | K19: -13.829969 | L19: -5.7576093 | M19: 0.31335947 | N19: -11.865113 | O19: -5.9882667 | P19: -4.7314486 | Q19: -7.6726643 | R19: -6.2320724 | S19: -1.4935658 | T19: -8.4422111 | U19: -6.309519 | V19: -5.4407692 | W19: -7.776105 | X19: -10.774881 | Y19: -4.7651566 | Z19: -19.388353 | AA19: -5.910356 | AB19: -2.1962556 | AC19: -11.722273 | AD19: -5.7696626 | AE19: -5.9357463 | AF19: -5.6237853 | AG19: -15.306776 | AH19: -17.409426 | AI19: -13.349194 | AJ19: -2.1977822 | AK19: -5.3622322 | AL19: 1.1904986 | AM19: -5.9040137 | AN19: 5.6689342 | AO19: -19.561145
B20: Mayo | C20: -11.501304 | D20: -6.2591865 | E20: -18.609135 | F20: -12.509857 | G20: -6.803629 | H20: -23.380215 | I20: -10.919917 | J20: -3.1325429 | K20: -22.080144 | L20: -9.4733548 | M20: -2.1181904 | N20: -16.920544 | O20: -10.714759 | P20: -7.2154549 | Q20: -15.442308 | R20: -12.264468 | S20: -6.3659036 | T20: -15.020747 | U20: -12.10983 | V20: -9.5448761 | W20: -16.485107 | X20: -12.850936 | Y20: -6.1786719 | Z20: -22.511027 | AA20: -9.9276599 | AB20: -3.8849664 | AC20: -19.339687 | AD20: -11.292497 | AE20: -9.2106651 | AF20: -13.119641 | AG20: -18.404883 | AH20: -19.786498 | AI20: -17.098715 | AJ20: -6.4636497 | AK20: -8.9216818 | AL20: -3.858209 | AM20: -10.918919 | AN20: 1.9080502 | AO20: -26.027397
B21: Junio | C21: -15.927138 | D21: -9.4596917 | E21: -24.710867 | F21: -17.5032 | G21: -10.996838 | H21: -29.877094 | I21: -15.529985 | J21: -6.6555899 | K21: -28.364639 | L21: -13.346922 | M21: -4.3069847 | N21: -22.436227 | O21: -15.416921 | P21: -10.391978 | Q21: -22.259067 | R21: -17.905375 | S21: -11.041862 | T21: -21.092248 | U21: -17.120748 | V21: -13.215757 | W21: -23.751902 | X21: -15.102107 | Y21: -7.2721112 | Z21: -26.57743 | AA21: -13.338306 | AB21: -5.9090273 | AC21: -24.898369 | AD21: -16.298406 | AE21: -11.568745 | AF21: -20.417212 | AG21: -20.334591 | AH21: -20.861433 | AI21: -19.830831 | AJ21: -9.8599924 | AK21: -11.459972 | AL21: -8.1844451 | AM21: -14.44135 | AN21: -0.62187168 | AO21: -30.667854
B22: Julio | C22: -19.800616 | D22: -12.301542 | E22: -29.942094 | F22: -22.13732 | G22: -14.418892 | H22: -36.506817 | I22: -19.191193 | J22: -9.4470085 | K22: -33.294458 | L22: -16.289901 | M22: -5.8880024 | N22: -26.669273 | O22: -19.363046 | P22: -13.238322 | Q22: -27.714943 | R22: -22.365391 | S22: -15.29812 | T22: -25.662237 | U22: -21.567104 | V22: -16.680674 | W22: -29.794826 | X22: -18.200697 | Y22: -8.7133356 | Z22: -32.269036 | AA22: -16.655285 | AB22: -8.2880172 | AC22: -29.637023 | AD22: -20.228198 | AE22: -13.982392 | AF22: -25.645314 | AG22: -22.06715 | AH22: -22.622735 | AI22: -21.533987 | AJ22: -13.441335 | AK22: -14.57977 | AL22: -12.256903 | AM22: -17.554573 | AN22: -4.2666321 | AO22: -33.231334
B23: Agosto | C23: -22.981111 | D23: -14.81571 | E23: -33.994164 | F23: -25.713351 | G23: -17.508737 | H23: -40.82769 | I23: -22.148974 | J23: -11.841819 | K23: -37.110703 | L23: -18.631285 | M23: -7.262984 | N23: -29.922945 | O23: -22.866886 | P23: -15.967452 | Q23: -32.266585 | R23: -25.99815 | S23: -18.644543 | T23: -29.432172 | U23: -25.093297 | V23: -19.564368 | W23: -34.341146 | X23: -20.555199 | Y23: -9.6837266 | Z23: -36.808566 | AA23: -19.945487 | AB23: -11.048731 | AC23: -33.712269 | AD23: -23.528342 | AE23: -16.051216 | AF23: -29.977236 | AG23: -23.652193 | AH23: -23.540526 | AI23: -23.75914 | AJ23: -16.426528 | AK23: -17.212725 | AL23: -15.61319 | AM23: -20.639784 | AN23: -6.9770076 | AO23: -36.747229
B24: Septiembre | C24: -25.399346 | D24: -16.947133 | E24: -36.781751 | F24: -28.774861 | G24: -20.207644 | H24: -44.406124 | I24: -24.434649 | J24: -13.741436 | K24: -40.014728 | L24: -20.38301 | M24: -8.6808018 | N24: -32.007157 | O24: -25.334339 | P24: -18.372825 | Q24: -34.80612 | R24: -27.845342 | S24: -21.165323 | T24: -30.988806 | U24: -27.61431 | V24: -21.779083 | W24: -37.301813 | X24: -22.382609 | Y24: -10.40366 | Z24: -40.426392 | AA24: -22.69333 | AB24: -13.825835 | AC24: -36.381974 | AD24: -25.907772 | AE24: -17.50857 | AF24: -33.121744 | AG24: -24.785694 | AH24: -24.567089 | AI24: -24.994553 | AJ24: -18.928818 | AK24: -19.158373 | AL24: -18.692794 | AM24: -22.940217 | AN24: -8.6820926 | AO24: -39.692671
B25: Octubre | C25: -27.036295 | D25: -18.74367 | E25: -38.16964 | F25: -31.279733 | G25: -22.633395 | H25: -46.961562 | I25: -26.070175 | J25: -15.342002 | K25: -41.690771 | L25: -21.244672 | M25: -9.6698285 | N25: -32.704113 | O25: -26.654185 | P25: -20.172362 | Q25: -35.410791 | R25: -28.636812 | S25: -23.241288 | T25: -31.192919 | U25: -29.383704 | V25: -23.54797 | W25: -38.998101 | X25: -23.182967 | Y25: -11.025565 | Z25: -41.611046 | AA25: -24.761973 | AB25: -16.179741 | AC25: -37.993332 | AD25: -27.861315 | AE25: -19.216943 | AF25: -35.243274 | AG25: -24.905394 | AH25: -25.269499 | AI25: -24.559304 | AJ25: -20.615613 | AK25: -20.932955 | AL25: -20.291245 | AM25: -24.275876 | AN25: -10.751424 | AO25: -40.163586
B26: Noviembre | C26: -28.260734 | D26: -20.273181 | E26: -38.956103 | F26: -33.412116 | G26: -24.810119 | H26: -48.907991 | I26: -27.37815 | J26: -16.714593 | K26: -42.884515 | L26: -21.787012 | M26: -10.558693 | N26: -32.91122 | O26: -27.530108 | P26: -21.964928 | Q26: -35.024133 | R26: -28.986114 | S26: -24.417352 | T26: -31.154536 | U26: -30.560502 | V26: -24.795442 | W26: -39.995226 | X26: -23.689627 | Y26: -11.452794 | Z26: -42.350711 | AA26: -26.240042 | AB26: -18.097785 | AC26: -38.787305 | AD26: -29.170107 | AE26: -20.426096 | AF26: -36.595411 | AG26: -25.057073 | AH26: -25.890155 | AI26: -24.271974 | AJ26: -21.786947 | AK26: -22.544514 | AL26: -21.017351 | AM26: -25.244566 | AN26: -12.987437 | AO26: -39.785154
B27: Diciembre | C27: -29.092193 | D27: -21.435111 | E27: -39.281399 | F27: -35.077283 | G27: -26.70408 | H27: -50.117169 | I27: -28.275686 | J27: -17.800466 | K27: -43.424338 | L27: -22.36438 | M27: -11.428576 | N27: -33.151517 | O27: -27.767237 | P27: -23.19194 | Q27: -33.859283 | R27: -29.225144 | S27: -25.440049 | T27: -31.018932 | U27: -31.247658 | V27: -25.446655 | W27: -40.592349 | X27: -23.837899 | Y27: -11.620259 | Z27: -42.596725 | AA27: -27.433599 | AB27: -19.576993 | AC27: -39.479356 | AD27: -30.037606 | AE27: -21.153512 | AF27: -37.5371 | AG27: -25.161795 | AH27: -25.894333 | AI27: -24.48465 | AJ27: -22.791154 | AK27: -23.947714 | AL27: -21.622377 | AM27: -25.550231 | AN27: -14.520202 | AO27: -38.855044
A28: 2021(p) | B28: Enero | C28: -37.469315 | D28: -35.218167 | E28: -40.361074 | F28: -53.149096 | G28: -49.467861 | H28: -60.534264 | I28: -37.228732 | J28: -29.685621 | K28: -47.248734 | L28: -28.851783 | M28: -23.614355 | N28: -34.160416 | O28: -28.373298 | P28: -33.705219 | Q28: -22.232675 | R28: -32.815785 | S28: -36.33334 | T28: -31.180211 | U28: -40.114058 | V28: -37.803486 | W28: -43.463321 | X28: -22.357826 | Y28: -11.201922 | Z28: -40.763104 | AA28: -41.392969 | AB28: -38.578863 | AC28: -45.662008 | AD28: -37.998537 | AE28: -31.635855 | AF28: -43.201632 | AG28: -27.355072 | AH28: -31.967422 | AI28: -23.573843 | AJ28: -29.118262 | AK28: -36.885543 | AL28: -22.136908 | AM28: -27.416268 | AN28: -24.899598 | AO28: -31.12426
B29: Febrero | C29: -37.722353 | D29: -35.238475 | E29: -40.953591 | F29: -54.021808 | G29: -49.431975 | H29: -62.95307 | I29: -38.834652 | J29: -30.982323 | K29: -49.564437 | L29: -27.255416 | M29: -22.506031 | N29: -32.203405 | O29: -28.554674 | P29: -33.239232 | Q29: -23.042703 | R29: -32.669184 | S29: -38.819085 | T29: -29.816944 | U29: -39.965653 | V29: -37.913722 | W29: -43.013062 | X29: -22.496373 | Y29: -11.303208 | Z29: -40.96076 | AA29: -40.458582 | AB29: -38.138218 | AC29: -44.002271 | AD29: -37.073116 | AE29: -30.757882 | AF29: -42.285955 | AG29: -26.311521 | AH29: -30.422622 | AI29: -22.836319 | AJ29: -24.80165 | AK29: -27.489461 | AL29: -22.311991 | AM29: -29.311586 | AN29: -30.125354 | AO29: -28.125
B30: Marzo | C30: -35.449175 | D30: -34.420508 | E30: -36.843324 | F30: -53.032013 | G30: -48.761686 | H30: -61.60065 | I30: -36.589568 | J30: -31.335119 | K30: -44.326517 | L30: -24.788477 | M30: -21.391778 | N30: -28.429523 | O30: -25.668144 | P30: -32.271402 | Q30: -17.51582 | R30: -29.201221 | S30: -39.114322 | T30: -24.36392 | U30: -37.74524 | V30: -37.024033 | W30: -38.865799 | X30: -19.437333 | Y30: -8.5197205 | Z30: -37.403554 | AA30: -38.05269 | AB30: -37.082043 | AC30: -39.594105 | AD30: -33.860656 | AE30: -28.274993 | AF30: -38.441783 | AG30: -22.734863 | AH30: -28.085846 | AI30: -18.181547 | AJ30: -21.08785 | AK30: -23.818797 | AL30: -18.454714 | AM30: -27.739614 | AN30: -29.972376 | AO30: -24.498797
B31: Abril | C31: -31.316994 | D31: -32.86958 | E31: -29.024097 | F31: -50.449356 | G31: -47.413361 | H31: -57.092992 | I31: -31.983738 | J31: -30.102879 | K31: -35.097211 | L31: -20.681903 | M31: -20.094152 | N31: -21.354895 | O31: -21.148577 | P31: -31.462288 | Q31: -6.885725 | R31: -22.969313 | S31: -36.041528 | T31: -16.409423 | U31: -33.409186 | V31: -35.474522 | W31: -29.834284 | X31: -15.658234 | Y31: -5.4896613 | Z31: -32.876194 | AA31: -34.377115 | AB31: -35.763755 | AC31: -31.973118 | AD31: -28.395206 | AE31: -25.987988 | AF31: -30.502563 | AG31: -16.825391 | AH31: -24.818141 | AI31: -9.7327639 | AJ31: -17.379294 | AK31: -20.229022 | AL31: -14.525587 | AM31: -23.89773 | AN31: -28.712446 | AO31: -16.433799
B32: Mayo | C32: -27.948826 | D32: -30.861682 | E32: -23.39997 | F32: -47.97808 | G32: -45.497425 | H32: -53.72611 | I32: -28.232786 | J32: -28.289381 | K32: -28.131956 | L32: -17.651161 | M32: -18.505371 | N32: -16.632163 | O32: -17.414118 | P32: -29.65136 | Q32: 0.72685155 | R32: -19.009398 | S32: -32.496056 | T32: -12.065517 | U32: -29.389253 | V32: -32.97193 | W32: -22.770093 | X32: -12.902609 | Y32: -4.0201987 | Z32: -28.473035 | AA32: -32.190558 | AB32: -34.711323 | AC32: -27.511953 | AD32: -23.187986 | AE32: -23.328992 | AF32: -23.058662 | AG32: -13.455184 | AH32: -22.069532 | AI32: -5.5752767 | AJ32: -13.83146 | AK32: -15.825114 | AL32: -11.829543 | AM32: -20.26699 | AN32: -26.81883 | AO32: -9.6354167
B33: Junio | C33: -24.037097 | D33: -28.607141 | E33: -16.57302 | F33: -44.866296 | G33: -43.112279 | H33: -49.100265 | I33: -23.887221 | J33: -25.941937 | K33: -20.015019 | L33: -14.300593 | M33: -16.99143 | N33: -10.962688 | O33: -12.760085 | P33: -27.573267 | Q33: 10.489043 | R33: -13.880253 | S33: -28.374373 | T33: -6.2931488 | U33: -24.92599 | V33: -30.389887 | W33: -14.365512 | X33: -9.5374027 | Y33: -2.6019603 | Z33: -22.374249 | AA33: -29.892121 | AB33: -33.504239 | AC33: -22.850474 | AD33: -17.832917 | AE33: -20.94887 | AF33: -14.817697 | AG33: -10.401966 | AH33: -20.677654 | AI33: -0.70277541 | AJ33: -11.025154 | AK33: -12.648861 | AL33: -9.385421 | AM33: -17.223552 | AN33: -25.671551 | AO33: -3.0053943
B34: Julio | C34: -19.780864 | D34: -26.193323 | E34: -8.9252859 | F34: -41.624464 | G34: -40.717213 | H34: -43.901088 | I34: -19.388556 | J34: -23.633479 | K34: -11.048195 | L34: -11.131533 | M34: -15.499347 | N34: -5.5380598 | O34: -7.8474946 | P34: -25.20895 | Q34: 20.568581 | R34: -8.3193583 | S34: -25.349401 | T34: 0.73267758 | U34: -19.933883 | V34: -27.572893 | W34: -4.6687137 | X34: -4.8758845 | Y34: -0.667086 | Z34: -13.287426 | AA34: -26.59046 | AB34: -31.502611 | AC34: -16.65695 | AD34: -12.521857 | AE34: -18.239531 | AF34: -6.784947 | AG34: -6.3685711 | AH34: -17.78782 | AI34: 4.4377831 | AJ34: -7.3577347 | AK34: -9.1324524 | AL34: -5.5601947 | AM34: -13.587604 | AN34: -23.421837 | AO34: 3.0476627
B35: Agosto | C35: -15.686631 | D35: -23.689386 | E35: -1.7567668 | F35: -38.375059 | G35: -38.188699 | H35: -38.853658 | I35: -15.157966 | J35: -21.397347 | K35: -2.4618653 | L35: -8.2347531 | M35: -13.910362 | N35: -0.77452596 | O35: -2.9008708 | P35: -22.711949 | Q35: 30.584346 | R35: -3.2146476 | S35: -22.259638 | T35: 7.0386442 | U35: -15.294499 | V35: -24.660836 | W35: 3.8976948 | X35: -0.68616669 | Y35: 1.1124375 | Z35: -4.5294141 | AA35: -22.867888 | AB35: -28.847741 | AC35: -10.451074 | AD35: -7.5711921 | AE35: -15.749766 | AF35: 0.88555382 | AG35: -2.6328932 | AH35: -15.152404 | AI35: 9.3918513 | AJ35: -3.9231124 | AK35: -5.7906601 | AL35: -2.0277124 | AM35: -9.7451737 | AN35: -20.187508 | AO35: 8.3597213
B36: Septiembre | C36: -12.015355 | D36: -21.27782 | E36: 4.3717528 | F36: -34.984557 | G36: -35.636269 | H36: -33.277907 | I36: -11.44637 | J36: -19.451851 | K36: 5.3264636 | L36: -5.4757379 | M36: -12.116105 | N36: 3.3832519 | O36: 1.2881692 | P36: -20.037802 | Q36: 37.618113 | R36: 0.45092415 | S36: -19.438138 | T36: 11.142529 | U36: -11.722487 | V36: -22.19674 | W36: 9.9717832 | X36: 3.2189407 | Y36: 2.6038329 | Z36: 4.612407 | AA36: -19.36763 | AB36: -26.003215 | AC36: -5.4925459 | AD36: -3.3043392 | AE36: -13.650433 | AF36: 7.6563217 | AG36: 0.72696202 | AH36: -11.847878 | AI36: 12.809669 | AJ36: -0.19502729 | AK36: -2.8789671 | AL36: 2.5487554 | AM36: -6.6577333 | AN36: -17.48375 | AO36: 12.602901
B37: Octubre | C37: -8.9486925 | D37: -18.911267 | E37: 8.6289493 | F37: -31.644246 | G37: -33.057021 | H37: -27.906584 | I37: -8.2745055 | J37: -17.74751 | K37: 11.751311 | L37: -3.560961 | M37: -10.555199 | N37: 5.733689 | O37: 4.0334265 | P37: -17.543937 | Q37: 40.060607 | R37: 2.6426479 | S37: -16.902443 | T37: 12.972109 | U37: -8.5439242 | V37: -19.752389 | W37: 14.599009 | X37: 5.9640096 | Y37: 4.0064679 | Z37: 10.485534 | AA37: -16.151603 | AB37: -23.354201 | AC37: -1.1407997 | AD37: 0.89370584 | AE37: -10.190847 | AF37: 12.702124 | AG37: 2.70118 | AH37: -7.5849695 | AI37: 12.386358 | AJ37: 3.0892695 | AK37: 0.35858919 | AL37: 5.8579336 | AM37: -4.4120493 | AN37: -14.589666 | AO37: 13.420912
B39: Fuente: DANE, EMA
B40: (p): Cifra provisional
B41: Nota metodológica: Regiones: Bogotá DC, Cartagena, Región Central (Boyacá, Cundinamarca, Huila y Tolima), Región Costa Caribe (Atlántico, Cesar, La Guajira y Magdalena), Región Eje Cafetero (Caldas, Quindío y Risaralda), Antioquia, San Andrés y Providencia, Región Pacífico (Valle del Cauca, Cauca, Nariño y Chocó), Región Santanderes (Santander y Norte de Santander), Llanos Orinoquía (Meta, Casanare, Arauca y Vichada), Región Golfo Morrosquillo y Sabana (Bolívar, Córdoba y Sucre), Región Amazonía (Amazonas, Caquetá, Guainía, Putumayo, Guaviare y Vaupés).
B45: Variación año corrido=((valor de los meses transcurridos del año de referencia-valor de los mismos meses transcurridos del año anterior)/(valor de los meses transcurridos del año anterior))*100
B46: 1 El resto del personal lo conforman las siguientes categorías de contratación: los Propietarios, Socios y Familiares sin remuneración, el Temporal Directo, Temporal contratado a través de Agencias y los Aprendices.
B47: ='1.1 V.A Ing.real'!B45 -> Actualizado el 15 de diciembre de 2021

Sheet 2.3 V.12Meses Per.categ
L4: Inicio
A7: ENCUESTA MENSUAL DE ALOJAMIENTO - EMA
A10: 2.3 Variaciones 12 meses del personal total y por categoría
A11: Total nacional y 12 regiones
A12: ='1.3 V.12Meses Ing.real'!A12 -> Diciembre 2020 - octubre 2021
A14: Año | B14: Meses | C14: Total nacional | F14: Bogotá D.C. | I14: Cartagena | L14: Central | O14: Caribe | R14: Eje Cafetero | U14: Antioquia | X14: San Andrés y Providencia | AA14: Pacífico | AD14: Santanderes | AG14: Llanos Orinoquía | AJ14: Golfo de Morrosquillo y Sabana | AM14: Amazonía
C15: Total del personal | D15: Personal permanente | E15: Resto de personal | F15: Total del personal | G15: Personal permanente | H15: Resto de personal | I15: Total del personal | J15: Personal permanente | K15: Resto de personal | L15: Total del personal | M15: Personal permanente | N15: Resto de personal | O15: Total del personal | P15: Personal permanente | Q15: Resto de personal | R15: Total del personal | S15: Personal permanente | T15: Resto de personal | U15: Total del personal | V15: Personal permanente | W15: Resto de personal | X15: Total del personal | Y15: Personal permanente | Z15: Resto de personal | AA15: Total del personal | AB15: Personal permanente | AC15: Resto de personal | AD15: Total del personal | AE15: Personal permanente | AF15: Resto de personal | AG15: Total del personal | AH15: Personal permanente | AI15: Resto de personal | AJ15: Total del personal | AK15: Personal permanente | AL15: Resto de personal | AM15: Total del personal | AN15: Personal permanente | AO15: Resto de personal
A16: 2020(p) | B16: Diciembre | C16: -29.092193 | D16: -21.435111 | E16: -39.281399 | F16: -35.077283 | G16: -26.70408 | H16: -50.117169 | I16: -28.275686 | J16: -17.800466 | K16: -43.424338 | L16: -22.36438 | M16: -11.428576 | N16: -33.151517 | O16: -27.767237 | P16: -23.19194 | Q16: -33.859283 | R16: -29.225144 | S16: -25.440049 | T16: -31.018932 | U16: -31.247658 | V16: -25.446655 | W16: -40.592349 | X16: -23.837899 | Y16: -11.620259 | Z16: -42.596725 | AA16: -27.433599 | AB16: -19.576993 | AC16: -39.479356 | AD16: -30.037606 | AE16: -21.153512 | AF16: -37.5371 | AG16: -25.161795 | AH16: -25.894333 | AI16: -24.48465 | AJ16: -22.791154 | AK16: -23.947714 | AL16: -21.622377 | AM16: -25.550231 | AN16: -14.520202 | AO16: -38.855044
